<?xml version = "1.0" ?>
<robot name="Alex">

	<!-- 8020 Base, Chest and Head -->
	<link name="Pelvis">
	  <inertial>
		<mass value="10.0"/>
		<origin rpy="0 0 0" xyz="0.02 0.0 -0.02"/>
		<inertia ixx="0.0942" ixy="6.05E-06" ixz="0.000379" iyy="0.0416" iyz="3.37E-07" izz="0.112" />
	  </inertial>
		<visual>
			<geometry>
				<mesh filename="package://alex_description/meshes/Torso_Base_and_Head.obj"/>
			</geometry>
			<origin rpy="0.0 0.0 0.0" xyz="0.0 0.0 0.37"/>
		</visual>
	</link>


	<!-- left upper arm joints -->
	<joint name="LeftShoulderPitch" type="revolute">
		<origin xyz="-0.0114 0.1 0.570" rpy="0.698132 0.0 0.0"   />
		<axis xyz="0.0 1.0 0.0" />
		<parent link="Pelvis" />
		<child link="LeftShoulderPitchLink" />
		<limit effort="150.0" lower="-3.141592" upper="1.22173" velocity = "9.0" />
		<dynamics damping="0.05" friction="0.0"/>
	</joint>
	
	<joint name="LeftShoulderRoll" type="revolute">
		<origin rpy="-0.698132 0.0 0.0" xyz="0.0 0.15676000 -0.01300000" />
		<axis xyz="1 0 0" />
		<parent link="LeftShoulderPitchLink" />
		<child link="LeftShoulderRollLink" />
		<limit effort="150.0" lower="-0.349066" upper="2.79253" velocity = "9.0" />
		<dynamics damping="0.05" friction="0.0"/>
	</joint>
	
	<joint name="LeftShoulderYaw" type="revolute">
		<origin rpy="0.0 0.0 0.0" xyz="0.0 0.035 0.0" />
		<axis xyz="0.0 0.0 1.0" />
		<parent link="LeftShoulderRollLink" />
		<child link="LeftShoulderYawLink" />
		<limit effort="80.0" lower="-1.91986" upper="1.22173" velocity = "11.5" />
		<dynamics damping="0.05" friction="0.0"/>
	</joint>
	
	<joint name="LeftElbowPitch" type="revolute">
		<origin rpy="0.0 0.0 0.0" xyz="0.015 0.0 -0.3127" />
		<axis xyz="0.0 1.0 0.0" />
		<parent link="LeftShoulderYawLink" />
		<child link="LeftElbowPitchLink" />
		<limit effort="80.0" lower="-2.35619" upper="0.174532925" velocity = "11.5" />
		<dynamics damping="0.05" friction="0.0"/>
	</joint>
	
	<!-- left wrist joints -->
	<joint name="LeftWristYaw" type="revolute">
		<origin xyz="-0.015 0.0 0.0" rpy="0.0 0.0 0.0"   />
		<axis xyz="0.0 0.0 1.0" />
		<parent link="LeftElbowPitchLink" />
		<child link="LeftWristYawLink" />
		<limit effort="20.0" lower="-2.61799" upper="2.61799" velocity = "25.0" />
		<dynamics damping="0.05" friction="0.0"/>
	</joint>
	
	<joint name="LeftWristRoll" type="revolute">
		<origin xyz="0.0 -0.013 -0.25" rpy="0.0 0.0 0.0"/>
		<axis xyz="1 0 0" />
		<parent link="LeftWristYawLink" />
		<child link="LeftWristRollLink" />
		<limit effort="20.0" lower="-1.8326" upper="0.610865" velocity = "25.0" />
		<dynamics damping="0.05" friction="0.0"/>
	</joint>
	
	<joint name="LeftGripperYaw" type="revolute">
		<origin xyz="0.0 0.013 -0.031" rpy="0.0 0.0 0.0" />
		<axis xyz="0.0 0.0 1.0" />
		<parent link="LeftWristRollLink" />
		<child link="LeftGripperYawLink" />
		<limit effort="20.0" lower="-2.61799" upper="2.61799" velocity = "25.0" />
		<dynamics damping="0.05" friction="0.0"/>
	</joint>
	
	<!-- left upper arm links -->
	<link name="LeftShoulderPitchLink">
	  <inertial>
		<mass value="2.917"/>
		<origin rpy="0 0 0" xyz="-0.00117 0.1400097 -0.00621"/>
		<inertia ixx="0.0108367" ixy="1.356e-4" ixz="-2.666e-5" iyy="0.00498324" iyz="0.00090758" izz="0.01142661" />
	  </inertial>
	  <visual>
		<geometry>
		  <mesh filename="package://alex_description/meshes/cycloidal_arm/LeftShoulderPitchLink.obj"/>
		</geometry>
		<origin rpy="0.0 0.0 0.0" xyz="0.0 0.0 0.0"/>
	  </visual>
	</link>

	<link name="LeftShoulderRollLink">
	  <inertial>
		<mass value="0.971"/>
		<origin rpy="0 0 0" xyz="0.01251711 0.0188309 -0.03849849"/>
		<inertia ixx="0.002948452" ixy="1.38648e-4" ixz="-3.34518e-4" iyy="0.002358705" iyz="5.25478e-4" izz="0.00143661" />
	  </inertial>
	  <visual>
		<geometry>
		  <mesh filename="package://alex_description/meshes/cycloidal_arm/LeftShoulderRollLink.obj"/>
		</geometry>
		<origin rpy="0.0 0.0 0.0" xyz="0.0 0.0 0.0"/>
	  </visual>
	</link>

	<link name="LeftShoulderYawLink">
	  <inertial>
		<mass value="2.53059"/>
		<origin rpy="0 0 0" xyz="0.00479 0.00062 -0.3624141"/>
		<inertia ixx="0.02277422" ixy="5.053e-5" ixz="0.0012266" iyy="0.0225956" iyz="-2.571e-4" izz="0.00260312" />
	  </inertial>
	  <visual>
		<geometry>
		  <mesh filename="package://alex_description/meshes/cycloidal_arm/LeftShoulderYawLink.obj"/>
		</geometry>
		<origin rpy="0.0 0.0 0.0" xyz="0.0 0.0 0.0"/>
	  </visual>
	</link>
	
	<!-- left wrist links -->	
	<link name="LeftElbowPitchLink">
      <inertial>
        <mass value="0.4895385722366345"/>
        <origin xyz="-0.012039456382923622 -0.003781574950319319 -0.04998167188554722" rpy="0 0 0"/>        
      <inertia 
	    ixx="7.466682164602668E-4" 
		ixy="-4.9125185240164585E-6" 
		ixz="-3.118756072793259E-5" 
		iyy="6.697708130628391E-4" 
		iyz="1.4985943611036623E-4" 
		izz="4.976405971436793E-4" />    
	  </inertial>
      <visual>
        <geometry>
            <mesh filename="package://alex_description/meshes/cycloidal_arm/LeftElbowPitchLink.obj"/>
        </geometry>
        <origin rpy="0.0 0.0 0.0" xyz="0.0 0.0 0.0"/>
      </visual>
    </link>
	
	<link name="LeftWristYawLink">
    <inertial>
      <mass value="1.5075249788801466"/>
        <origin xyz="-0.0024383302867828187 -5.246795816220965E-4 -0.1300914213150444" rpy="0 0 0"/>        
		<inertia 
		  ixx="0.0036746953546519796" 
		  ixy="1.5200537475756135E-5" 
		  ixz="-1.3155829305043117E-5"
		  iyy="0.003955455275643572" 
		  iyz="-9.878441058198549E-5" 
		  izz="0.0014329681446651732" />    
		</inertial>
    <visual>
      <geometry>
        <mesh filename="package://alex_description/meshes/cycloidal_arm/LeftWristYawLink.obj"/>
      </geometry>
      <origin rpy="0.0 0.0 0.0" xyz="0.0 0.0 0.0"/>
    </visual>
    </link>
	
	
    <link name="LeftWristRollLink">
      <inertial>
        <mass value="0.6953487750589724"/>
        <origin xyz="1.5946763939368963E-4 0.012435479395687345 0.0016553711070014143" rpy="0 0 0"/>        
		<inertia 
		  ixx="5.09001424971436E-4"
		  ixy="-7.082123470616537E-6" 
		  ixz="-6.451042619821356E-6" 
		  iyy="5.251489793788867E-4" 
		  iyz="-1.2507083234598893E-6" 
		  izz="5.190882683529875E-4" />    
	  </inertial>
      <visual>
        <geometry>
            <mesh filename="package://alex_description/meshes/cycloidal_arm/LeftWristRollLink.obj"/>
        </geometry>
        <origin rpy="0.0 0.0 0.0" xyz="0.0 0.0 0.0"/>
      </visual>
    </link>

	
	<link name="LeftGripperYawLink">
	  <inertial>
		<mass value="0.2480"/>
		<origin rpy="0 0 0" xyz="-0.00014709 -0.00037325 0.01033255"/>
		<inertia 
		ixx="0.00013926" 
		ixy="3.991e-8" 
		ixz="4.497e-7" 
		iyy="0.00014236" 
		iyz="-7.218e-7" 
		izz="0.00011005" />
	  </inertial>
	  <visual>
		<geometry>
		  <mesh filename="package://alex_description/meshes/cycloidal_arm/LeftGripperYawLink.obj"/>
		</geometry>
		<origin rpy="0.0 0.0 0.0" xyz="0.0 0.0 0.0"/>
	  </visual>
	</link>
	
	<!-- Right Upper Arm Joints -->
	<joint name="RightShoulderPitch" type="revolute">
    <origin xyz="-0.0114 -0.1 0.570" rpy="-0.698132 0.0 0.0"   />
		<axis xyz="0.0 1.0 0.0" />
		<parent link="Pelvis" />
		<child link="RightShoulderPitchLink" />
		<limit effort="1000" lower="-3.141592" upper="1.22173" velocity = "100" />
		<dynamics damping="0.05" friction="0.0"/>
	</joint>
	<joint name="RightShoulderRoll" type="revolute">
    <origin rpy="0.698132 0.0 0.0" xyz="0.0 -0.15676000 -0.01300000" />
		<axis xyz="1 0 0" />
		<parent link="RightShoulderPitchLink" />
		<child link="RightShoulderRollLink" />
    <limit effort="1000" lower="-2.79253" upper="0.349066" velocity = "100" />
		<dynamics damping="0.05" friction="0.0"/>
	</joint>
	<joint name="RightShoulderYaw" type="revolute">
		<origin rpy="0.0 0.0 0.0" xyz="0.0 -0.035 0.0" />
		<axis xyz="0.0 0.0 1.0" />
		<parent link="RightShoulderRollLink" />
		<child link="RightShoulderYawLink" />
		<limit effort="1000" lower="-1.22173" upper="1.91986" velocity = "100" />
		<dynamics damping="0.05" friction="0.0"/>
	</joint>
	<joint name="RightElbowPitch" type="revolute">
		<origin rpy="0.0 0.0 0.0" xyz="0.015 0.0 -0.3127" />
		<axis xyz="0.0 1.0 0.0" />
		<parent link="RightShoulderYawLink" />
		<child link="RightElbowPitchLink" />
		<limit effort="1000" lower="-2.35619" upper="0.174532925" velocity = "100" />
		<dynamics damping="0.05" friction="0.0"/>
	</joint>

	<!-- right wrist joints -->
	<joint name="RightWristYaw" type="revolute">
		<origin xyz="-0.015 0.0 0.0" rpy="0.0 0.0 0.0"   />
		<axis xyz="0.0 0.0 1.0" />
		<parent link="RightElbowPitchLink" />
		<child link="RightWristYawLink" />
		<limit effort="20.0" lower="-2.61799" upper="2.61799" velocity = "25.0" />
		<dynamics damping="0.05" friction="0.0"/>
	</joint>
	
	<joint name="RightWristRoll" type="revolute">
		<origin xyz="0.0 0.013 -0.25" rpy="0.0 0.0 0.0"/>
		<axis xyz="1 0 0" />
		<parent link="RightWristYawLink" />
		<child link="RightWristRollLink" />
		<limit effort="20.0" lower="-0.610865" upper="1.8326" velocity = "25.0" />
		<dynamics damping="0.05" friction="0.0"/>
	</joint>
	
	<joint name="RightGripperYaw" type="revolute">
		<origin xyz="0.0 -0.013 -0.031" rpy="0.0 0.0 0.0" />
		<axis xyz="0.0 0.0 1.0" />
		<parent link="RightWristRollLink" />
		<child link="RightGripperYawLink" />
		<limit effort="20.0" lower="-2.61799" upper="2.61799" velocity = "25.0" />
		<dynamics damping="0.05" friction="0.0"/>
	</joint>
	
	<!-- Right Upper Arm Links -->
	<link name="RightShoulderPitchLink">
	  <inertial>
		<mass value="2.917"/>
		<origin rpy="0 0 0" xyz="-0.00117 -0.1400097 -0.00621"/>
		<inertia ixx="0.0108367" ixy="1.356e-4" ixz="-2.666e-5" iyy="0.00498324" iyz="0.00090758" izz="0.01142661" />
	  </inertial>
	  <visual>
		<geometry>
		  <mesh filename="package://alex_description/meshes/cycloidal_arm/RightShoulderPitchLink.obj"/>
		</geometry>
		<origin rpy="0.0 0.0 0.0" xyz="0.0 0.0 0.0"/>
	  </visual>
	</link>

	<link name="RightShoulderRollLink">
	  <inertial>
		<mass value="0.971"/>
		<origin rpy="0 0 0" xyz="0.01251711 -0.0188309 -0.03849849"/>
		<inertia ixx="0.002948452" ixy="-1.38648e-4" ixz="-3.34518e-4" iyy="0.002358705" iyz="-5.25478e-4" izz="0.00143661" />
	  </inertial>
	  <visual>
		<geometry>
		  <mesh filename="package://alex_description/meshes/cycloidal_arm/RightShoulderRollLink.obj"/>
		</geometry>
		<origin rpy="0.0 0.0 0.0" xyz="0.0 0.0 0.0"/>
	  </visual>
	</link>

	<link name="RightShoulderYawLink">
	  <inertial>
		<mass value="2.53059"/>
		<origin rpy="0 0 0" xyz="0.00479 0.00062 -0.3624141"/>
		<inertia ixx="0.02277422" ixy="5.053e-5" ixz="0.0012266" iyy="0.0225956" iyz="-2.571e-4" izz="0.00260312" />
	  </inertial>
	  <visual>
		<geometry>
		  <mesh filename="package://alex_description/meshes/cycloidal_arm/RightShoulderYawLink.obj"/>
		</geometry>
		<origin rpy="0.0 0.0 0.0" xyz="0.0 0.0 0.0"/>
	  </visual>
	</link>

	<!-- right wrist links -->	
	<link name="RightElbowPitchLink">
      <inertial>
        <mass value="0.4895385722366345"/>
        <origin xyz="-0.012039456382923622 0.003781574950319319 -0.04998167188554722" rpy="0 0 0"/>        
		  <inertia 
			ixx="7.466682164602668E-4" 
			ixy="-4.9125185240164585E-6" 
			ixz="-3.118756072793259E-5" 
			iyy="6.697708130628391E-4" 
			iyz="1.4985943611036623E-4" 
			izz="4.976405971436793E-4" />    
	  </inertial>
      <visual>
        <geometry>
            <mesh filename="package://alex_description/meshes/cycloidal_arm/RightElbowPitchLink.obj"/>
        </geometry>
        <origin rpy="0.0 0.0 0.0" xyz="0.0 0.0 0.0"/>
      </visual>
    </link>
	
	<link name="RightWristYawLink">
    <inertial>
      <mass value="1.5075249788801466"/>
        <origin xyz="-0.0024383302867828187 5.246795816220965E-4 -0.1300914213150444" rpy="0 0 0"/>        
		<inertia 
		  ixx="0.0036746953546519796" 
		  ixy="1.5200537475756135E-5" 
		  ixz="-1.3155829305043117E-5"
		  iyy="0.003955455275643572" 
		  iyz="-9.878441058198549E-5" 
		  izz="0.0014329681446651732" />    
		</inertial>
    <visual>
      <geometry>
        <mesh filename="package://alex_description/meshes/cycloidal_arm/RightWristYawLink.obj"/>
      </geometry>
      <origin rpy="0.0 0.0 0.0" xyz="0.0 0.0 0.0"/>
    </visual>
    </link>
	
    <link name="RightWristRollLink">
      <inertial>
        <mass value="0.6953487750589724"/>
        <origin xyz="1.5946763939368963E-4 -0.012435479395687345 0.0016553711070014143" rpy="0 0 0"/>        
		<inertia 
		  ixx="5.09001424971436E-4"
		  ixy="-7.082123470616537E-6" 
		  ixz="-6.451042619821356E-6" 
		  iyy="5.251489793788867E-4" 
		  iyz="-1.2507083234598893E-6" 
		  izz="5.190882683529875E-4" />    
	  </inertial>
      <visual>
        <geometry>
            <mesh filename="package://alex_description/meshes/cycloidal_arm/RightWristRollLink.obj"/>
        </geometry>
        <origin rpy="0.0 0.0 0.0" xyz="0.0 0.0 0.0"/>
      </visual>
    </link>

	<link name="RightGripperYawLink">
	  <inertial>
		<mass value="0.2480"/>
		<origin rpy="0 0 0" xyz="-0.00014709 0.00037325 0.01033255"/>
		<inertia 
		ixx="0.00013926" 
		ixy="3.991e-8" 
		ixz="4.497e-7" 
		iyy="0.00014236" 
		iyz="-7.218e-7" 
		izz="0.00011005" />
	  </inertial>
	  <visual>
		<geometry>
		  <mesh filename="package://alex_description/meshes/cycloidal_arm/RightGripperYawLink.obj"/>
		</geometry>
		<origin rpy="0.0 0.0 0.0" xyz="0.0 0.0 0.0"/>
	  </visual>
	</link>

	<!-- ~~~~~~~~~~~~~~~~~~~~~~~~~~~~~~~~~~~~~~~~~~~~~~~~~~~~~~~~~~~~~~~~~~~~~~~~~~~~~~~~~~~~~ -->
	<!-- Right Gripper Fixed Joints -->
	<joint name="RightGrippertAttachmentFixedJoint" type="fixed">
		<origin rpy="0 0 0" xyz="0 0 -0.0210000"/>
		<parent link="RightGripperYawLink"/>
		<child link="RightBarrettPalmLink"/>
	</joint>

	<!-- Right Barrett Gripper -->
	<link name="RightBarrettPalmLink">
        <inertial>
            <mass value="0.944"/>
            <origin xyz="0.0 -0.00482 -0.04594" rpy="1.57079632679 0.0 -1.57079632679"/>
            <inertia ixx="0.00150" ixy="-2.1617e-6" ixz="-4.765e-7" iyy="0.001223" iyz="2.018e-6" izz="0.00117"/>
		</inertial>
<!--		<visual>-->
<!--			<origin xyz="0 0 0" rpy="1.57079632679  0 -1.57079632679"/>-->
<!--			<geometry>-->
<!--				<mesh filename="package://barrett_description/meshes/bh280/hand_base.dae"/>-->
<!--			</geometry>-->
<!--			<material name="">-->
<!--				<color rgba="0.752941176470588 0.752941176470588 0.752941176470588 1"/>-->
<!--			</material>-->
<!--		</visual>-->
	</link>

	<!-- Right Hand Dumbbell Fixed Joint -->
	<joint name="RightHandDumbbellAttachmentFixedJoint" type="fixed">
		<origin rpy="0 0 0" xyz="0 0 -0.027"/>
		<parent link="RightBarrettPalmLink"/>
		<child link="RightHandDumbbellLink"/>
	</joint>

	<!-- Right Hand Dumbbell -->
	<link name="RightHandDumbbellLink">
		<inertial>
			<mass value="3.956"/>
			<!--			<mass value="8.49188"/>-->
			<!--			<mass value="10.75984"/>-->
			<origin xyz="0.0 0.0 0.0" rpy="0.0 0.0 0.0"/>
			<inertia ixx="0.00739373" ixy="0.0" ixz="0.0" iyy="0.03371325" iyz="0.0" izz="0.03371325"/>
			<!--			<inertia ixx="0.02190854" ixy="0.0" ixz="0.0" iyy="0.07315278" iyz="0.0" izz="0.07315278"/>-->
			<!--			<inertia ixx="0.02916602" ixy="0.0" ixz="0.0" iyy="0.10145919" iyz="0.0" izz="0.10145919"/>-->
		</inertial>
	</link>
	<!-- ~~~~~~~~~~~~~~~~~~~~~~~~~~~~~~~~~~~~~~~~~~~~~~~~~~~~~~~~~~~~~~~~~~~~~~~~~~~~~~~~~~~~~ -->

	<!-- ~~~~~~~~~~ Right Barret Hand ~~~~~~~~~~ -->
<!--	<link name="bh280/hand_base">-->
<!--		<inertial>-->
<!--			<origin xyz="5.0019e-005 -0.0044561 0.037268"/>-->
<!--			<mass value="0.60858"/>-->
<!--			<inertia-->
<!--					ixx="0.0006986" ixy="2.7577e-007" ixz="-7.8138e-007"-->
<!--					iyy="0.00050354" iyz="-6.44e-005"-->
<!--					izz="0.00062253"/>-->
<!--		</inertial>-->
<!--		<visual>-->
<!--			<origin xyz="0 0 0" rpy="0.0 0 0"/>-->
<!--			<geometry>-->
<!--				<mesh filename="package://barrett_description/meshes/bh280/hand_base.dae"/>-->
<!--			</geometry>-->
<!--			<material name="">-->
<!--				<color rgba="0.752941176470588 0.752941176470588 0.752941176470588 1"/>-->
<!--			</material>-->
<!--		</visual>-->
<!--		<collision>-->
<!--			<geometry>-->
<!--				<mesh filename="package://barrett_description/meshes/bh280/hand_base_collision.STL"/>-->
<!--			</geometry>-->
<!--		</collision>-->
<!--	</link>-->

<!--	<link name="bh280/finger0_0">-->
<!--		<inertial>-->
<!--			<origin xyz="0.030616 -7.3219e-005 -0.011201"/>-->
<!--			<mass value="0.14109"/>-->
<!--			<inertia-->
<!--					ixx="2.0672e-005" ixy="2.6024e-007" ixz="6.3481e-006"-->
<!--					iyy="7.4105e-005" iyz="1.7118e-008"-->
<!--					izz="6.8207e-005"/>-->
<!--		</inertial>-->
<!--		<visual>-->
<!--			<origin xyz="0 0 0" rpy="0 0 0"/>-->
<!--			<geometry>-->
<!--				<mesh filename="package://barrett_description/meshes/bh280/finger0_0.dae"/>-->
<!--			</geometry>-->
<!--			<material name="">-->
<!--				<color rgba="0.752941176470588 0.752941176470588 0.752941176470588 1"/>-->
<!--			</material>-->
<!--		</visual>-->
<!--		<collision>-->
<!--			<geometry>-->
<!--				<mesh filename="package://barrett_description/meshes/bh280/finger0_0_collision.STL"/>-->
<!--			</geometry>-->
<!--		</collision>-->
<!--	</link>-->

<!--	<joint name="bh280/j00" type="fixed">-->
<!--		<origin xyz="-0.025 0 0.0754000000000003" rpy="-9.27906974436996E-30 -2.56739074444568E-16 -1.5707963267949"/>-->
<!--		<parent link="bh280/hand_base"/>-->
<!--		<child link="bh280/finger0_0"/>-->
<!--		<axis xyz="0 0 -1"/>-->
<!--		<limit effort="0" lower="0" upper="3.14159265359" velocity="2.0"/>-->
<!--	</joint>-->

<!--	<link name="bh280/finger0_1">-->
<!--		<inertial>-->
<!--			<origin xyz="0.23133 0.00078642 0.00052792"/>-->
<!--			<mass value="0.062139"/>-->
<!--			<inertia-->
<!--					ixx="4.8162e-006" ixy="5.7981e-007" ixz="-7.2483e-007"-->
<!--					iyy="4.3317e-005" iyz="-2.6653e-009"-->
<!--					izz="4.4441e-005"/>-->
<!--		</inertial>-->
<!--		<visual>-->
<!--			<origin xyz="0 0 0" rpy="0 0 0"/>-->
<!--			<geometry>-->
<!--				<mesh filename="package://barrett_description/meshes/bh280/finger0_1.dae"/>-->
<!--			</geometry>-->
<!--			<material name="">-->
<!--				<color rgba="0.752941176470588 0.752941176470588 0.752941176470588 1"/>-->
<!--			</material>-->
<!--		</visual>-->
<!--		<collision>-->
<!--			<geometry>-->
<!--				<mesh filename="package://barrett_description/meshes/bh280/finger0_1_collision.STL"/>-->
<!--			</geometry>-->
<!--		</collision>-->
<!--	</link>-->

<!--	<joint name="bh280/j01" type="fixed">-->
<!--		<origin xyz="0.0500000000000007 0.000799999999999971 0" rpy="1.5707963267949 0 0"/>-->
<!--		<parent link="bh280/finger0_0"/>-->
<!--		<child link="bh280/finger0_1"/>-->
<!--		<axis xyz="0 0 1"/>-->
<!--		<limit effort="0" lower="0" upper="2.44346095279" velocity="2.0"/>-->
<!--	</joint>-->

<!--	<link name="bh280/finger0_2">-->
<!--		<inertial>-->
<!--			<origin xyz="0.02295 0.0010739 0.00041752"/>-->
<!--			<mass value="0.04166"/>-->
<!--			<inertia-->
<!--					ixx="3.1199e-006" ixy="4.5115e-007" ixz="-2.9813e-007"-->
<!--					iyy="1.6948e-005" iyz="-1.8635e-008"-->
<!--					izz="1.5809e-005"/>-->
<!--		</inertial>-->
<!--		<visual>-->
<!--			<origin xyz="0 0 0" rpy="0 0 0"/>-->
<!--			<geometry>-->
<!--				<mesh filename="package://barrett_description/meshes/bh280/finger0_2.dae"/>-->
<!--			</geometry>-->
<!--			<material name="">-->
<!--				<color rgba="0.898039215686275 0.917647058823529 0.929411764705882 1"/>-->
<!--			</material>-->
<!--		</visual>-->
<!--		<collision>-->
<!--			<geometry>-->
<!--				<mesh filename="package://barrett_description/meshes/bh280/finger0_2_collision.STL"/>-->
<!--			</geometry>-->
<!--		</collision>-->
<!--	</link>-->

<!--	<joint name="bh280/j02" type="fixed">-->
<!--		<origin xyz="0.069935684739622 0.00300000000000003 0.000200000000006934" rpy="-3.77533479986348E-14 -4.45260733378639E-14 0.698131700822416"/>-->
<!--		<parent link="bh280/finger0_1"/>-->
<!--		<child link="bh280/finger0_2"/>-->
<!--		<axis xyz="0 0 1"/>-->
<!--		<limit effort="0" lower="0" upper="0.837758040957" velocity="2.0"/>-->
<!--		<mimic joint="bh280/j01" multiplier="0.321428571429" offset="0.0"/>-->
<!--	</joint>-->

<!--	<link name="bh280/finger1_0">-->
<!--		<inertial>-->
<!--			<origin xyz="0.030616 -7.3219e-005 -0.011201"/>-->
<!--			<mass value="0.14109"/>-->
<!--			<inertia-->
<!--					ixx="2.0672e-005" ixy="2.6024e-007" ixz="6.3481e-006"-->
<!--					iyy="7.4105e-005" iyz="1.7118e-008"-->
<!--					izz="6.8207e-005"/>-->
<!--		</inertial>-->
<!--		<visual>-->
<!--			<origin xyz="0 0 0" rpy="0 0 0"/>-->
<!--			<geometry>-->
<!--				<mesh filename="package://barrett_description/meshes/bh280/finger1_0.dae"/>-->
<!--			</geometry>-->
<!--			<material name="">-->
<!--				<color rgba="0.752941176470588 0.752941176470588 0.752941176470588 1"/>-->
<!--			</material>-->
<!--		</visual>-->
<!--		<collision>-->
<!--			<geometry>-->
<!--				<mesh filename="package://barrett_description/meshes/bh280/finger1_0_collision.STL"/>-->
<!--			</geometry>-->
<!--		</collision>-->
<!--	</link>-->

<!--	<joint name="bh280/j10" type="fixed">-->
<!--		<origin xyz="0.025 0 0.0754" rpy="-9.2871E-30 -0.0058448 -1.5708"/>-->
<!--		<parent link="bh280/hand_base"/>-->
<!--		<child link="bh280/finger1_0"/>-->
<!--		<axis xyz="0.0058448 0 0.99998"/>-->
<!--		<limit effort="0" lower="0" upper="3.14159265359" velocity="2.0"/>-->
<!--		<mimic joint="bh280/j00" multiplier="1" offset="0"/>-->
<!--	</joint>-->

<!--	<link name="bh280/finger1_1">-->
<!--		<inertial>-->
<!--			<origin xyz="0.023133 0.00078642 0.00052792"/>-->
<!--			<mass value="0.062139"/>-->
<!--			<inertia-->
<!--					ixx="4.8162e-006" ixy="5.7981e-007" ixz="-7.2483e-007"-->
<!--					iyy="4.3317e-005" iyz="-2.6653e-009"-->
<!--					izz="4.4441e-005"/>-->
<!--		</inertial>-->
<!--		<visual>-->
<!--			<origin xyz="0 0 0" rpy="0 0 0"/>-->
<!--			<geometry>-->
<!--				<mesh filename="package://barrett_description/meshes/bh280/finger1_1.dae"/>-->
<!--			</geometry>-->
<!--			<material name="">-->
<!--				<color rgba="0.752941176470588 0.752941176470588 0.752941176470588 1"/>-->
<!--			</material>-->
<!--		</visual>-->
<!--		<collision>-->
<!--			<geometry>-->
<!--				<mesh filename="package://barrett_description/meshes/bh280/finger1_1_collision.STL"/>-->
<!--			</geometry>-->
<!--		</collision>-->
<!--	</link>-->

<!--	<joint name="bh280/j11" type="fixed">-->
<!--		<origin xyz="0.0499991459461259 0.000799999999999367 -0.000292240753933679" rpy="1.5707963267949 0 -4.93038065763132E-32"/>-->
<!--		<parent link="bh280/finger1_0"/>-->
<!--		<child link="bh280/finger1_1"/>-->
<!--		<axis xyz="0 0 1"/>-->
<!--		<limit effort="0" lower="0" upper="2.44346095279" velocity="2.0"/>-->
<!--	</joint>-->

<!--	<link name="bh280/finger1_2">-->
<!--		<inertial>-->
<!--			<origin xyz="0.02295 0.0010739 0.00041752"/>-->
<!--			<mass value="0.04166"/>-->
<!--			<inertia-->
<!--					ixx="3.1199e-006" ixy="4.5115e-007" ixz="-2.9813e-007"-->
<!--					iyy="1.6948e-005" iyz="-1.8635e-008"-->
<!--					izz="1.5809e-005"/>-->
<!--		</inertial>-->
<!--		<visual>-->
<!--			<origin xyz="0 0 0" rpy="0 0 0"/>-->
<!--			<geometry>-->
<!--				<mesh filename="package://barrett_description/meshes/bh280/finger1_2.dae"/>-->
<!--			</geometry>-->
<!--			<material name="">-->
<!--				<color rgba="0.898039215686275 0.917647058823529 0.929411764705882 1"/>-->
<!--			</material>-->
<!--		</visual>-->
<!--		<collision>-->
<!--			<geometry>-->
<!--				<mesh filename="package://barrett_description/meshes/bh280/finger1_2_collision.STL"/>-->
<!--			</geometry>-->
<!--		</collision>-->
<!--	</link>-->

<!--	<joint name="bh280/j12" type="fixed">-->
<!--		<origin xyz="0.0699356847396015 0.00300000000003377 0.000199999999999378" rpy="1.95799899548702E-16 2.29686057908074E-16 0.700079983587682"/>-->
<!--		<parent link="bh280/finger1_1"/>-->
<!--		<child link="bh280/finger1_2"/>-->
<!--		<axis xyz="0 0 1"/>-->
<!--		<limit effort="0" lower="0" upper="0.837758040957" velocity="2.0"/>-->
<!--		<mimic joint="bh280/j11" multiplier="0.321428571429" offset="0.0"/>-->
<!--	</joint>-->

<!--	<link name="bh280/finger2_1">-->
<!--		<inertial>-->
<!--			<origin xyz="0.023133 0.00078642 0.00052792"/>-->
<!--			<mass value="0.062139"/>-->
<!--			<inertia-->
<!--					ixx="4.8162e-006" ixy="5.7981e-007" ixz="-7.2483e-007"-->
<!--					iyy="4.3317e-005" iyz="-2.6653e-009"-->
<!--					izz="4.4441e-005"/>-->
<!--		</inertial>-->
<!--		<visual>-->
<!--			<origin xyz="0 0 0" rpy="0 0 0"/>-->
<!--			<geometry>-->
<!--				<mesh filename="package://barrett_description/meshes/bh280/finger2_1.dae"/>-->
<!--			</geometry>-->
<!--			<material name="">-->
<!--				<color rgba="0.752941176470588 0.752941176470588 0.752941176470588 1"/>-->
<!--			</material>-->
<!--		</visual>-->
<!--		<collision>-->
<!--			<geometry>-->
<!--				<mesh filename="package://barrett_description/meshes/bh280/finger2_1_collision.STL"/>-->
<!--			</geometry>-->
<!--		</collision>-->
<!--	</link>-->

<!--	<joint name="bh280/j21" type="fixed">-->
<!--		<origin xyz="-0.000799999999999992 0.05 0.0754000000000003" rpy="1.5707963267949 2.77555756156289E-17 1.5707963267949"/>-->
<!--		<parent link="bh280/hand_base"/>-->
<!--		<child link="bh280/finger2_1"/>-->
<!--		<axis xyz="0 0 1"/>-->
<!--		<limit effort="0" lower="0" upper="2.44346095279" velocity="2.0"/>-->
<!--	</joint>-->

<!--	<link name="bh280/finger2_2">-->
<!--		<inertial>-->
<!--			<origin xyz="0.02295 0.0010739 0.00041752"/>-->
<!--			<mass value="0.04166"/>-->
<!--			<inertia-->
<!--					ixx="3.1199e-006" ixy="4.5115e-007" ixz="-2.9813e-007"-->
<!--					iyy="1.6948e-005" iyz="-1.8635e-008"-->
<!--					izz="1.5809e-005"/>-->
<!--		</inertial>-->
<!--		<visual>-->
<!--			<origin xyz="0 0 0" rpy="0 0 0"/>-->
<!--			<geometry>-->
<!--				<mesh filename="package://barrett_description/meshes/bh280/finger2_2.dae"/>-->
<!--			</geometry>-->
<!--			<material name="">-->
<!--				<color rgba="0.898039215686275 0.917647058823529 0.929411764705882 1"/>-->
<!--			</material>-->
<!--		</visual>-->
<!--		<collision>-->
<!--			<geometry>-->
<!--				<mesh filename="package://barrett_description/meshes/bh280/finger2_2_collision.STL"/>-->
<!--			</geometry>-->
<!--		</collision>-->
<!--	</link>-->

<!--	<joint name="bh280/j22" type="fixed">-->
<!--		<origin xyz="0.0699356847396236 0.00300000000000011 0.000199999999999993" rpy="5.6276902721421E-16 5.75421399737176E-16 0.698131700797743"/>-->
<!--		<parent link="bh280/finger2_1"/>-->
<!--		<child link="bh280/finger2_2"/>-->
<!--		<axis xyz="0 0 1"/>-->
<!--		<limit effort="0" lower="0" upper="0.837758040957" velocity="2.0"/>-->
<!--		<mimic joint="bh280/j21" multiplier="0.321428571429" offset="0.0"/>-->
<!--	</joint>-->
	<!-- ~~~~~~~~~~~~~~~~~~~~~~~~~~~~~~ -->

	<!-- ~~~~~~~~~~~~~~~~~~~~~~~~~~~~~~~~~~~~~~~~~~~~~~~~~~~~~~~~~~~~~~~~~~~~~~~~~~~~~~~~~~~~~ -->
	<joint name="LeftGrippertAttachmentFixedJoint" type="fixed">
		<origin rpy="0 0 0" xyz="0 0 -0.0210000"/>
		<parent link="LeftGripperYawLink"/>
		<child link="LeftBarrettPalmLink"/>
	</joint>

	<!-- Left Barrett Gripper -->
	<link name="LeftBarrettPalmLink">
		<inertial>
			<mass value="0.944"/>
			<origin xyz="0.0 -0.00482 -0.04594" rpy="1.57079632679 0.0 -1.57079632679"/>
			<inertia ixx="0.00150" ixy="-2.1617e-6" ixz="-4.765e-7" iyy="0.001223" iyz="2.018e-6" izz="0.00117"/>
		</inertial>
<!--		<visual>-->
<!--			<origin xyz="0 0 0" rpy="1.57079632679  0 -1.57079632679"/>-->
<!--			<geometry>-->
<!--				<mesh filename="package://barrett_description/meshes/bh280/hand_base.dae"/>-->
<!--			</geometry>-->
<!--			<material name="">-->
<!--				<color rgba="0.752941176470588 0.752941176470588 0.752941176470588 1"/>-->
<!--			</material>-->
<!--		</visual>-->
	</link>

	<!-- Left Hand Dumbbell Fixed Joint -->
	<joint name="LeftHandDumbbellAttachmentFixedJoint" type="fixed">
		<origin rpy="0 0 0" xyz="0 0 -0.027"/>
		<parent link="LeftBarrettPalmLink"/>
		<child link="LeftHandDumbbellLink"/>
	</joint>

	<!-- Left Hand Dumbbell -->
	<link name="LeftHandDumbbellLink">
		<inertial>
			<mass value="3.956"/>
<!--			<mass value="8.49188"/>-->
<!--			<mass value="10.75984"/>-->
			<origin xyz="0.0 0.0 0.0" rpy="0.0 0.0 0.0"/>
			<inertia ixx="0.00739373" ixy="0.0" ixz="0.0" iyy="0.03371325" iyz="0.0" izz="0.03371325"/>
<!--			<inertia ixx="0.02190854" ixy="0.0" ixz="0.0" iyy="0.07315278" iyz="0.0" izz="0.07315278"/>-->
<!--			<inertia ixx="0.02916602" ixy="0.0" ixz="0.0" iyy="0.10145919" iyz="0.0" izz="0.10145919"/>-->
		</inertial>
	</link>
	<!-- ~~~~~~~~~~~~~~~~~~~~~~~~~~~~~~~~~~~~~~~~~~~~~~~~~~~~~~~~~~~~~~~~~~~~~~~~~~~~~~~~~~~~~ -->

<!--	&lt;!&ndash; Left Sake Gripper &ndash;&gt;-->
<!--	<link name="LeftSakePalmLink">-->
<!--		<inertial>-->
<!--			<mass value="0.3"/>-->
<!--			<origin rpy="0 0 0" xyz="0.01 0.0 -0.06"/>-->
<!--			<inertia ixx="5e-4" ixy="0.0" ixz="0.0" iyy="3e-4" iyz="0.0" izz="3e-4" />-->
<!--		</inertial>-->
<!--		<visual name="LeftSakePalmLinkVisual">-->
<!--			<origin xyz="0.0 0.0 0.0" rpy="0 0 0"/>-->
<!--			<geometry>-->
<!--				<mesh filename="package://sake_description/meshes/SakePalmLink.obj"/>-->
<!--			</geometry>-->
<!--		</visual>-->
<!--	</link>-->
<!--	-->
<!--	<joint name="LeftSakeBaseFingerJoint1" type="fixed">-->
<!--        <origin xyz="0.0 0.0299 -0.0754" rpy="-0.25 0.0 0.0"/>-->
<!--        <axis xyz="1.0 0.0 0.0"/>-->
<!--        <parent link="LeftSakePalmLink"/>-->
<!--        <child link="LeftSakeBaseFingerLink1"/>-->
<!--        <dynamics damping="0.05" friction="0.0"/>-->
<!--        <limit effort="1.0" lower="-0.06" upper="1.9" velocity="3.67"/>-->
<!--    </joint>-->
<!--    <joint name="LeftSakeKnuckle1" type="fixed">-->
<!--        <origin xyz="0.0 0.0 -0.052" rpy="0.0 0.0 0.0"/>-->
<!--        <axis xyz="1.0 0.0 0.0"/>-->
<!--        <parent link="LeftSakeBaseFingerLink1"/>-->
<!--        <child link="LeftSakeFingerTip1"/>-->
<!--        <dynamics damping="0.05" friction="0.0"/>-->
<!--        <limit effort="1.0" lower="-1.0" upper="0.0" velocity="3.67"/>-->
<!--    </joint>-->
<!--    <joint name="LeftSakeBaseFingerJoint2" type="fixed">-->
<!--        <origin xyz="0.0 -0.0299 -0.0754" rpy="0.25 0.0 0.0"/>-->
<!--        <axis xyz="-1.0 0.0 0.0"/>-->
<!--        <parent link="LeftSakePalmLink"/>-->
<!--        <child link="LeftSakeBaseFingerLink2"/>-->
<!--        <dynamics damping="0.05" friction="0.0"/>-->
<!--        <limit effort="1.0" lower="-0.06" upper="1.9" velocity="3.67"/>-->
<!--    </joint>-->
<!--    <joint name="LeftSakeKnuckle2" type="fixed">-->
<!--        <origin xyz="0.0 0.0 -0.052" rpy="0.0 0.0 0.0"/>-->
<!--        <axis xyz="-1.0 0.0 0.0"/>-->
<!--        <parent link="LeftSakeBaseFingerLink2"/>-->
<!--        <child link="LeftSakeFingerTip2"/>-->
<!--        <dynamics damping="0.05" friction="0.0"/>-->
<!--        <limit effort="1.0" lower="-1.0" upper="0.0" velocity="3.67"/>-->
<!--    </joint>-->
<!--	-->
<!--	<link name="LeftSakeBaseFingerLink1">-->
<!--        <inertial>-->
<!--            <mass value="0.05"/>-->
<!--            <origin xyz="0.0 0.0 0.0" rpy="0.0 0.0 0.0"/>-->
<!--            <inertia ixx="0.01" ixy="0.0" ixz="0.0" iyy="0.01" iyz="0.0" izz="0.01"/>-->
<!--        </inertial>-->
<!--        <visual name="LeftSakeBaseFingerLink1Visual">-->
<!--            <origin xyz="0.0 0.0 0.0" rpy="1.571 0.0 3.142"/>-->
<!--            <geometry>-->
<!--                <mesh filename="package://sake_description/meshes/sake_finger_knuckle.obj"/>-->
<!--            </geometry>-->
<!--        </visual>-->
<!--    </link>-->
<!--    <link name="LeftSakeFingerTip1">-->
<!--        <inertial>-->
<!--            <mass value="0.05"/>-->
<!--            <origin xyz="0.0 0.0 0.0" rpy="0.0 0.0 0.0"/>-->
<!--            <inertia ixx="0.01" ixy="0.0" ixz="0.0" iyy="0.01" iyz="0.0" izz="0.01"/>-->
<!--        </inertial>-->
<!--        <visual name="LeftSakeFingerTip1Visual">-->
<!--            <origin xyz="0.0 0.0 0.0" rpy="1.571 0.0 3.142"/>-->
<!--            <geometry>-->
<!--                <mesh filename="package://sake_description/meshes/sake_finger_tip.obj"/>-->
<!--            </geometry>-->
<!--        </visual>-->
<!--    </link>-->
<!--    <link name="LeftSakeBaseFingerLink2">-->
<!--        <inertial>-->
<!--            <mass value="0.05"/>-->
<!--            <origin xyz="0.0 0.0 0.0" rpy="0.0 0.0 0.0"/>-->
<!--            <inertia ixx="0.01" ixy="0.0" ixz="0.0" iyy="0.01" iyz="0.0" izz="0.01"/>-->
<!--        </inertial>-->
<!--        <visual name="LeftSakeBaseFingerLink2Visual">-->
<!--            <origin xyz="0.0 0.0 0.0" rpy="1.571 0.0 0.0"/>-->
<!--            <geometry>-->
<!--                <mesh filename="package://sake_description/meshes/sake_finger_knuckle.obj"/>-->
<!--            </geometry>-->
<!--        </visual>-->
<!--    </link>-->
<!--    <link name="LeftSakeFingerTip2">-->
<!--        <inertial>-->
<!--            <mass value="0.05"/>-->
<!--            <origin xyz="0.0 0.0 0.0" rpy="0.0 0.0 0.0"/>-->
<!--            <inertia ixx="0.01" ixy="0.0" ixz="0.0" iyy="0.01" iyz="0.0" izz="0.01"/>-->
<!--        </inertial>-->
<!--        <visual name="LeftSakeFingerTip2Visual">-->
<!--            <origin xyz="0.0 0.0 0.0" rpy="1.571 0.0 0.0"/>-->
<!--            <geometry>-->
<!--                <mesh filename="package://sake_description/meshes/sake_finger_tip.obj"/>-->
<!--            </geometry>-->
<!--        </visual>-->
<!--    </link>-->
</robot>
