<?xml version = "1.0" ?>
<robot name="Alex">

		<!-- 8020 Base, Chest and Head -->
	<link name="Pelvis">
		<inertial>
			<mass value="10.0"/>
			<origin rpy="0 0 0" xyz="0.02 0.0 -0.02"/>
			<inertia ixx="0.0942" ixy="6.05E-06" ixz="0.000379" iyy="0.0416" iyz="3.37E-07" izz="0.112" />
		</inertial>
		<visual>
			<geometry>
				<mesh filename="package://alex_description/meshes/TorsoFixedBaseWithoutSpine.obj"/>
			</geometry>
			<origin rpy="0.0 0.0 0.0" xyz="0.0 0.0 0.37"/>
		</visual>
	</link>

	<!-- Neck Joints -->
	<joint name="NeckYaw" type="revolute">
		<origin rpy="0 0 0" xyz="0.000094 -0.000003 0.462793" /> <!-- placeholder for the joint location -->
		<axis xyz="0 0 1" />
		<parent link="Pelvis" />
		<child link="NeckYawLink" />
		<limit effort="20" lower="-1.5708" upper="1.5708" velocity = "20" />
		<dynamics damping="0.05" friction="0.0"/>
	</joint>

	<joint name="NeckPitch" type="revolute">
		<origin rpy="0 0 0" xyz="0.025 -0.027544 0.245212" />
		<axis xyz="0 1 0" />
		<parent link="NeckYawLink" />
		<child link="Head" />
		<limit effort="20" lower="-1.0472" upper="1.0472" velocity = "20" />
		<dynamics damping="0.05" friction="0.0"/>
	</joint>

	<!-- Neck and Head -->
	<!-- Inertia data is a placeholder -->
	<link name="NeckYawLink">
	  <inertial>
		<mass value="0.708"/>
		<origin rpy="0 0 0" xyz="0.011651 0.010332 0.147202"/>
		<inertia ixx="0.0063417" ixy="-0.0000441" ixz="-0.0007117" iyy="0.0064004" iyz="-0.0004412" izz="0.0004435" />
	  </inertial>
<!--	  &lt;!&ndash;visual>-->
<!--			<geometry>-->
<!--				<mesh filename="package://alex_description/meshes/NeckYaw.obj"/>-->
<!--			</geometry>-->
<!--			<origin rpy="0.0 0.0 0.0" xyz="0.0 0.0 0.0"/>-->
<!--	   </visual&ndash;&gt;	-->
	</link>

	<link name="Head">
	 <inertial>
		<mass value="1.615"/>
		<origin rpy="0 0 0" xyz="0.01967 0.023998 0.022356"/>
		<inertia ixx="0.0058084" ixy="-0.0001142" ixz="0.0007803" iyy="0.0069663" iyz="-0.0001353" izz="0.0063497" />
	  </inertial>
	  <visual>
			<geometry>
				<mesh filename="package://alex_description/meshes/Head.obj"/>
			</geometry>
			<origin rpy="0.0 0.0 0.0" xyz="0.0 0.0 0.0"/>
		  </visual>
	</link>

	<!-- TORSO IMU's NOTE: We currently have 3 fixed IMU's because we have fixed spine. This will change after we get a working spine-->
	<!-- TorsoLeftIMU-->
	<link name="TorsoLeftIMULink">
		<inertial>
			<mass value="0"/>
			<origin rpy="0 0 0" xyz="0 0 0"/>
			<inertia ixx="0.0" ixy="0.0" ixz="0.0" iyy="0.0" iyz="0.0" izz="0.0"/>
		</inertial>
	</link>
	<joint name="TorsoLeftIMUJoint" type="fixed">
		<origin rpy="1.570796 0 -1.570796" xyz="-0.102655 0.034047 0.488646"/>
		<axis xyz="0 0 1"/>
		<parent link="Pelvis"/>
		<child link="TorsoLeftIMULink"/>
	</joint>
	<gazebo reference="TorsoLeftIMULink">
		<sensor name="TorsoLeftIMU" type="imu">
			<always_on>true</always_on>
			<imu>
				<noise>
					<type>gaussian</type>
					<rate>
						<mean>0</mean>
						<stddev>0.0002</stddev>
						<bias_mean>7.5e-06</bias_mean>
						<bias_stddev>8e-07</bias_stddev>
					</rate>
					<accel>
						<mean>0</mean>
						<stddev>0.017</stddev>
						<bias_mean>0.1</bias_mean>
						<bias_stddev>0.001</bias_stddev>
					</accel>
				</noise>
			</imu>
		</sensor>
	</gazebo>
	<!-- TorsoRightIMU-->
	<link name="TorsoRightIMULink">
		<inertial>
			<mass value="0"/>
			<origin rpy="0 0 0" xyz="0 0 0"/>
			<inertia ixx="0.0" ixy="0.0" ixz="0.0" iyy="0.0" iyz="0.0" izz="0.0"/>
		</inertial>
	</link>
	<joint name="TorsoRightIMUJoint" type="fixed">
		<origin rpy="1.570796 0 -1.570796" xyz="-0.105655 -0.059053 0.488646"/>
		<axis xyz="0 0 1"/>
		<parent link="Pelvis"/>
		<child link="TorsoRightIMULink"/>
	</joint>
	<gazebo reference="TorsoRightIMULink">
		<sensor name="TorsoRightIMU" type="imu">
			<always_on>true</always_on>
			<imu>
				<noise>
					<type>gaussian</type>
					<rate>
						<mean>0</mean>
						<stddev>0.0002</stddev>
						<bias_mean>7.5e-06</bias_mean>
						<bias_stddev>8e-07</bias_stddev>
					</rate>
					<accel>
						<mean>0</mean>
						<stddev>0.017</stddev>
						<bias_mean>0.1</bias_mean>
						<bias_stddev>0.001</bias_stddev>
					</accel>
				</noise>
			</imu>
		</sensor>
	</gazebo>

	<!-- LEFT ARM -->
	<!-- left upper arm joints -->
	<joint name="LeftShoulderPitch" type="revolute">
		<origin xyz="-0.0114 0.1 0.407" rpy="0.698132 0.0 0.0"   />
		<axis xyz="0.0 1.0 0.0" />
		<parent link="Pelvis" />
		<child link="LeftShoulderPitchLink" />
		<limit effort="150.0" lower="-3.141592" upper="1.22173" velocity = "9.0" />
		<dynamics damping="0.05" friction="0.0"/>
	</joint>

	<joint name="LeftShoulderRoll" type="revolute">
		<origin rpy="-0.698132 0.0 0.0" xyz="0.0 0.15676000 -0.01300000" />
		<axis xyz="1 0 0" />
		<parent link="LeftShoulderPitchLink" />
		<child link="LeftShoulderRollLink" />
		<limit effort="150.0" lower="-0.349066" upper="2.79253" velocity = "9.0" />
		<dynamics damping="0.05" friction="0.0"/>
	</joint>

	<joint name="LeftShoulderYaw" type="revolute">
		<origin rpy="0.0 0.0 0.0" xyz="0.0 0.035 0.0" />
		<axis xyz="0.0 0.0 1.0" />
		<parent link="LeftShoulderRollLink" />
		<child link="LeftShoulderYawLink" />
		<limit effort="80.0" lower="-1.91986" upper="1.22173" velocity = "11.5" />
		<dynamics damping="0.05" friction="0.0"/>
	</joint>

	<joint name="LeftElbowPitch" type="revolute">
		<origin rpy="0.0 0.0 0.0" xyz="0.015 0.0 -0.3127" />
		<axis xyz="0.0 1.0 0.0" />
		<parent link="LeftShoulderYawLink" />
		<child link="LeftElbowPitchLink" />
		<limit effort="80.0" lower="-2.35619" upper="0.174532925" velocity = "11.5" />
		<dynamics damping="0.05" friction="0.0"/>
	</joint>

	<!-- left wrist joints -->
	<joint name="LeftWristYaw" type="revolute">
		<origin xyz="-0.015 0.0 0.0" rpy="0.0 0.0 0.0"   />
		<axis xyz="0.0 0.0 1.0" />
		<parent link="LeftElbowPitchLink" />
		<child link="LeftWristYawLink" />
		<limit effort="20.0" lower="-2.61799" upper="2.61799" velocity = "25.0" />
		<dynamics damping="0.05" friction="0.0"/>
	</joint>

	<joint name="LeftWristRoll" type="revolute">
		<origin xyz="0.0 -0.013 -0.25" rpy="0.0 0.0 0.0"/>
		<axis xyz="1 0 0" />
		<parent link="LeftWristYawLink" />
		<child link="LeftWristRollLink" />
		<limit effort="20.0" lower="-1.8326" upper="0.610865" velocity = "25.0" />
		<dynamics damping="0.05" friction="0.0"/>
	</joint>

	<joint name="LeftGripperYaw" type="revolute">
		<origin xyz="0.0 0.013 -0.031" rpy="0.0 0.0 0.0" />
		<axis xyz="0.0 0.0 1.0" />
		<parent link="LeftWristRollLink" />
		<child link="LeftGripperYawLink" />
		<limit effort="20.0" lower="-2.61799" upper="2.61799" velocity = "25.0" />
		<dynamics damping="0.05" friction="0.0"/>
	</joint>

	<!-- left upper arm links -->
	<link name="LeftShoulderPitchLink">
		<inertial>
			<mass value="2.99"/>
			<origin
					rpy="0 0 0"
					xyz="-0.00264 0.12135 -0.006824"/>
			<inertia ixx="0.0111046" ixy="0.0002882" ixz="-0.000054" iyy="0.0051699" iyz="0.0009318" izz="0.01176" />
		</inertial>
		<visual>
			<geometry>
				<mesh filename="package://alex_description/meshes/cycloidal_arm/LeftShoulderPitchLink.obj"/>
			</geometry>
			<origin rpy="0.0 0.0 0.0" xyz="0.0 0.0 0.0"/>
		</visual>
	</link>

	<link name="LeftShoulderRollLink">
		<inertial>
			<mass value="0.972"/>
			<origin
					rpy="0 0 0"
					xyz="0.01251711 0.0188309 -0.03849849"/>
			<inertia ixx="0.0029485" ixy="0.0001386" ixz="-0.0003345" iyy="0.0023587" iyz="0.0005255" izz="0.0014366" />
		</inertial>
		<visual>
			<geometry>
				<mesh filename="package://alex_description/meshes/cycloidal_arm/LeftShoulderRollLink_shortBicep.obj"/>
			</geometry>
			<origin rpy="0.0 0.0 0.0" xyz="0.0 0.0 0.0"/>
		</visual>
	</link>

	<link name="LeftShoulderYawLink">
		<inertial>
			<mass value="2.91"/>
			<origin
					rpy="0 0 0"
					xyz="0.00510403 0.00314332 -0.21695413"/>
			<inertia ixx="0.0267829" ixy="-0.000011" ixz="0.0015998" iyy="0.0265514" iyz="0.0004426" izz="0.003052" />
		</inertial>
		<visual>
			<geometry>
				<mesh filename="package://alex_description/meshes/cycloidal_arm/LeftShoulderYawLink.obj"/>
			</geometry>
			<origin rpy="0.0 0.0 0.0" xyz="0.0 0.0 0.0867"/>
		</visual>
	</link>

	<!-- left wrist links -->
	<link name="LeftElbowPitchLink">
		<inertial>
			<mass value="0.45"/>
			<origin
					rpy="0 0 0"
					xyz="-0.01180322 -0.0035763 -0.04946747"/>

			<inertia ixx="0.0007362" ixy="-0.0000088" ixz="-0.0000292" iyy="0.0006567" iyz="0.0001499" izz="0.0004897" />
		</inertial>
		<visual>
			<geometry>
				<mesh filename="package://alex_description/meshes/cycloidal_arm/LeftElbowPitchLink.obj"/>
			</geometry>
			<origin rpy="0.0 0.0 0.0" xyz="0.0 0.0 0.0"/>
		</visual>
	</link>

	<link name="LeftWristYawLink">
		<inertial>
			<mass value="1.547"/> <!-- This is a measured value. Refer to https://docs.google.com/spreadsheets/d/1VXWFJk3VJUsfkHrDaytB2INq94un1KytIOzcKJD0p44/edit?gid=0#gid=0  -->
			<origin
					rpy="0 0 0"
					xyz="-0.00263832 -0.00050534 -0.13018376"/>

			<inertia ixx="0.0037869" ixy="0.0000163" ixz="-0.0000252" iyy="0.004071" iyz="-0.0000924" izz="0.0015203" />
		</inertial>
		<visual>
			<geometry>
				<mesh filename="package://alex_description/meshes/cycloidal_arm/LeftWristYawLink.obj"/>
			</geometry>
			<origin rpy="0.0 0.0 0.0" xyz="0.0 0.0 0.0"/>
		</visual>
	</link>


	<link name="LeftWristRollLink">
		<inertial>
			<mass value="0.909"/> <!-- This is a measured value. Refer to https://docs.google.com/spreadsheets/d/1VXWFJk3VJUsfkHrDaytB2INq94un1KytIOzcKJD0p44/edit?gid=0#gid=0  -->
			<origin
					rpy="0 0 0"
					xyz="0.00004053 0.01038395 0.00035532"/>

			<inertia ixx="0.000477" ixy="-0.0000079" ixz="-0.0000097" iyy="0.0004902" iyz="-0.0000008" izz="0.000514" />
		</inertial>

		<visual> 
			<geometry>
				<mesh filename="package://alex_description/meshes/cycloidal_arm/LeftWristRollLink.obj"/>
			</geometry>
			<origin rpy="0.0 0.0 0.0" xyz="0.0 0.0 0.0"/>
		</visual>
	</link>


	<link name="LeftGripperYawLink">
		<inertial>
			<mass value="0.251"/>
			<origin
					rpy="0 0 0"
					xyz="-0.000217 -0.000349 0.009761"/>
			<inertia ixx="0.0000722" ixy="-0.0000016" ixz="-0.0000037" iyy="0.0000747" iyz="0.0000004" izz="0.0000324" />
		</inertial>
		<visual>
			<geometry>
				<mesh filename="package://alex_description/meshes/cycloidal_arm/LeftGripperYawLink.obj"/>
			</geometry>
			<origin rpy="0.0 0.0 0.0" xyz="0.0 0.0 0.0"/>
		</visual>
	</link>

	<!-- LEFT ARM IMU's -->
	<!-- Left Shoulder Pitch IMU Information -->
	<link name="LeftShoulderPitchIMULink">
		<inertial>
			<mass value="0"/>
			<origin rpy="0 0 0" xyz="0 0 0"/>
			<inertia ixx="0.0" ixy="0.0" ixz="0.0" iyy="0.0" iyz="0.0" izz="0.0"/>
		</inertial>
	</link>
	<joint name="LeftShoulderPitchIMUJoint" type="fixed">
		<origin rpy="-3.141592 0 -1.57079632679" xyz="0.01432621 0.0755071 -0.00245783"/>
		<axis xyz="0 0 1"/>
		<parent link="LeftShoulderPitchLink"/>
		<child link="LeftShoulderPitchIMULink"/>
	</joint>
	<gazebo reference="LeftShoulderPitchIMULink">
		<sensor name="LeftShoulderPitchIMU" type="imu">
			<always_on>true</always_on>
			<imu>
				<noise>
					<type>gaussian</type>
					<rate>
						<mean>0</mean>
						<stddev>0.0002</stddev>
						<bias_mean>7.5e-06</bias_mean>
						<bias_stddev>8e-07</bias_stddev>
					</rate>
					<accel>
						<mean>0</mean>
						<stddev>0.017</stddev>
						<bias_mean>0.1</bias_mean>
						<bias_stddev>0.001</bias_stddev>
					</accel>
				</noise>
			</imu>
		</sensor>
	</gazebo>

	<!-- Left ShoulderYaw IMU Note: in CAD this is the left bicep IMU -->
	<link name="LeftShoulderYawIMULink">
		<inertial>
			<mass value="0"/>
			<origin rpy="0 0 0" xyz="0 0 0"/>
			<inertia ixx="0.0" ixy="0.0" ixz="0.0" iyy="0.0" iyz="0.0" izz="0.0"/>
		</inertial>
	</link>
	<joint name="LeftShoulderYawIMUJoint" type="fixed">
		<origin rpy="1.570796 3.1415926 -0.314159" xyz="-0.00633723 -0.00669505 -0.19881468"/>
		<axis xyz="0 0 1"/>
		<parent link="LeftShoulderYawLink"/>
		<child link="LeftShoulderYawIMULink"/>
	</joint>
	<gazebo reference="LeftShoulderYawIMULink">
		<sensor name="LeftShoulderYawIMU" type="imu">
			<always_on>true</always_on>
			<pose>0 0 0 0 0 0</pose>
			<imu>
				<noise>
					<type>gaussian</type>
					<rate>
						<mean>0</mean>
						<stddev>0.0002</stddev>
						<bias_mean>7.5e-06</bias_mean>
						<bias_stddev>8e-07</bias_stddev>
					</rate>
					<accel>
						<mean>0</mean>
						<stddev>0.017</stddev>
						<bias_mean>0.1</bias_mean>
						<bias_stddev>0.001</bias_stddev>
					</accel>
				</noise>
			</imu>
		</sensor>
	</gazebo>

	<!-- Left Wrist Yaw IMU Note: in CAD this is the left bicep IMU -->
	<link name="LeftWristYawIMULink">
		<inertial>
			<mass value="0"/>
			<origin rpy="0 0 0" xyz="0 0 0"/>
			<inertia ixx="0.0" ixy="0.0" ixz="0.0" iyy="0.0" iyz="0.0" izz="0.0"/>
		</inertial>
	</link>

	<joint name="LeftWristYawIMUJoint" type="fixed">
		<origin rpy="1.571  0.0 1.571" xyz="-0.048986 0.011658 -0.149476"/>
		<axis xyz="0 0 1"/>
		<parent link="LeftWristYawLink"/>
		<child link="LeftWristYawIMULink"/>
	</joint>

	<gazebo reference="LeftWristYawIMULink">
		<sensor name="LeftWristYawIMU" type="imu">
			<always_on>true</always_on>
			<imu> <!-- placeholder tag for IMU --> </imu>
		</sensor>
	</gazebo>

	<!-- RIGHT ARM -->
	<!-- Right Upper Arm Joints -->
	<joint name="RightShoulderPitch" type="revolute">
		<origin xyz="-0.0114 -0.1 0.407" rpy="-0.698132 0.0 0.0"   />
		<axis xyz="0.0 1.0 0.0" />
		<parent link="Pelvis" />
		<child link="RightShoulderPitchLink" />
		<limit effort="1000" lower="-3.141592" upper="1.22173" velocity = "100" />
		<dynamics damping="0.05" friction="0.0"/>
	</joint>
	<joint name="RightShoulderRoll" type="revolute">
		<origin rpy="0.698132 0.0 0.0" xyz="0.0 -0.15676000 -0.01300000" />
		<axis xyz="1 0 0" />
		<parent link="RightShoulderPitchLink" />
		<child link="RightShoulderRollLink" />
		<limit effort="1000" lower="-2.79253" upper="0.349066" velocity = "100" />
		<dynamics damping="0.05" friction="0.0"/>
	</joint>
	<joint name="RightShoulderYaw" type="revolute">
		<origin rpy="0.0 0.0 0.0" xyz="0.0 -0.035 0.0" />
		<axis xyz="0.0 0.0 1.0" />
		<parent link="RightShoulderRollLink" />
		<child link="RightShoulderYawLink" />
		<limit effort="1000" lower="-1.22173" upper="1.91986" velocity = "100" />
		<dynamics damping="0.05" friction="0.0"/>
	</joint>
	<joint name="RightElbowPitch" type="revolute">
		<origin rpy="0.0 0.0 0.0" xyz="0.015 0.0 -0.3127" />
		<axis xyz="0.0 1.0 0.0" />
		<parent link="RightShoulderYawLink" />
		<child link="RightElbowPitchLink" />
		<limit effort="1000" lower="-2.35619" upper="0.174532925" velocity = "100" />
		<dynamics damping="0.05" friction="0.0"/>
	</joint>

	<!-- Right wrist joints -->
	<joint name="RightWristYaw" type="revolute">
		<origin xyz="-0.015 0.0 0.0" rpy="0.0 0.0 0.0"   />
		<axis xyz="0.0 0.0 1.0" />
		<parent link="RightElbowPitchLink" />
		<child link="RightWristYawLink" />
		<limit effort="20.0" lower="-2.61799" upper="2.61799" velocity = "25.0" />
		<dynamics damping="0.05" friction="0.0"/>
	</joint>

	<joint name="RightWristRoll" type="revolute">
		<origin xyz="0.0 0.013 -0.25" rpy="0.0 0.0 0.0"/>
		<axis xyz="1 0 0" />
		<parent link="RightWristYawLink" />
		<child link="RightWristRollLink" />
		<limit effort="20.0" lower="-0.610865" upper="1.8326" velocity = "25.0" />
		<dynamics damping="0.05" friction="0.0"/>
	</joint>

	<joint name="RightGripperYaw" type="revolute">
		<origin xyz="0.0 -0.013 -0.031" rpy="0.0 0.0 0.0" />
		<axis xyz="0.0 0.0 1.0" />
		<parent link="RightWristRollLink" />
		<child link="RightGripperYawLink" />
		<limit effort="20.0" lower="-2.61799" upper="2.61799" velocity = "25.0" />
		<dynamics damping="0.05" friction="0.0"/>
	</joint>

	<!-- Right Upper Arm Links -->
	<link name="RightShoulderPitchLink">
		<inertial>
			<mass value="2.99"/>
			<origin rpy="0 0 0" xyz="-0.00264 -0.12135 -0.006824"/>
			<inertia ixx="0.0110394" ixy="-0.0003041" ixz="-0.0000594" iyy="0.0051097" iyz="-0.0009183" izz="0.0116925" />
		</inertial>
		<visual>
			<geometry>
				<mesh filename="package://alex_description/meshes/cycloidal_arm/RightShoulderPitchLink.obj"/>
			</geometry>
			<origin rpy="0.0 0.0 0.0" xyz="0.0 0.0 0.0"/>
		</visual>
	</link>

	<link name="RightShoulderRollLink">
		<inertial>
			<mass value="0.972"/>
			<origin rpy="0 0 0" xyz="0.012489 -0.01882 -0.0385"/>
			<inertia ixx="0.002949" ixy="-0.000135" ixz="-0.0003358" iyy="0.0023603" iyz="-0.0005249" izz="0.0014377" />
		</inertial>
		<visual>
			<geometry>
				<mesh filename="package://alex_description/meshes/cycloidal_arm/RightShoulderRollLink_shortBicep.obj"/>
			</geometry>
			<origin rpy="0.0 0.0 0.0" xyz="0.0 0.0 0.0"/>
		</visual>
	</link>

	<link name="RightShoulderYawLink">
		<inertial>
			<mass value="2.91"/>
			<origin rpy="0 0 0" xyz="0.00524 -0.00274 -0.21745"/>
			<inertia ixx="0.0248699" ixy="0.0000211" ixz="0.0000211" iyy="0.0245973" iyz="-0.0004444" izz="0.0029883" />
		</inertial>
		<visual>
			<geometry>
				<mesh filename="package://alex_description/meshes/cycloidal_arm/RightShoulderYawLink.obj"/>
			</geometry>
			<origin rpy="0.0 0.0 0.0" xyz="0.0 0.0 0.0867"/>
		</visual>
	</link>

	<!-- right wrist links -->
	<link name="RightElbowPitchLink">
		<inertial>
			<mass value="0.45"/>
			<origin xyz="-0.0127 0.006913 -0.048421" rpy="0 0 0"/>
			<inertia ixx="0.0006446" ixy="-0.0000073" ixz="-0.0000345" iyy="0.000625" iyz="-0.0001257" izz="0.0003922" />
		</inertial>
		<visual>
			<geometry>
				<mesh filename="package://alex_description/meshes/cycloidal_arm/RightElbowPitchLink.obj"/>
			</geometry>
			<origin rpy="0.0 0.0 0.0" xyz="0.0 0.0 0.0"/>
		</visual>
	</link>

	<link name="RightWristYawLink">
		<inertial>
			<mass value="1.547"/> <!-- This is a measured value. Refer to https://docs.google.com/spreadsheets/d/1VXWFJk3VJUsfkHrDaytB2INq94un1KytIOzcKJD0p44/edit?gid=0#gid=0  -->
			<origin xyz="-0.002616 0.000462 -0.13019" rpy="0 0 0"/>
			<inertia ixx="0.0037805" ixy="-0.0000177" ixz="-0.000025" iyy="0.0040639" iyz="0.00009" izz="0.0015151" />
		</inertial>
		<visual>
			<geometry>
				<mesh filename="package://alex_description/meshes/cycloidal_arm/RightWristYawLink.obj"/>
			</geometry>
			<origin rpy="0.0 0.0 0.0" xyz="0.0 0.0 0.0"/>
		</visual>
	</link>

	<link name="RightWristRollLink">
		<inertial>
			<mass value="0.909"/> <!-- This is a measured value. Refer to https://docs.google.com/spreadsheets/d/1VXWFJk3VJUsfkHrDaytB2INq94un1KytIOzcKJD0p44/edit?gid=0#gid=0  -->
			<origin xyz="-0.0000481 -0.012143 0.000196" rpy="0 0 0"/>
			<inertia ixx="0.0005535" ixy="0.0000081" ixz="-0.0000231" iyy="0.0005559" iyz="0.0000012" izz="0.0005893" />
		</inertial>
		<visual>
			<geometry>
				<mesh filename="package://alex_description/meshes/cycloidal_arm/RightWristRollLink.obj"/>
			</geometry>
			<origin rpy="0.0 0.0 0.0" xyz="0.0 0.0 0.0"/>
		</visual>
	</link>

	<link name="RightGripperYawLink">
		<inertial>
			<mass value="0.251"/>
			<origin rpy="0 0 0" xyz="-0.000217 -0.000349 0.009761"/>
			<inertia ixx="0.0000722" ixy="-0.0000016" ixz="-0.0000037" iyy="0.0000747" iyz="0.0000004" izz="0.0000324" />
		</inertial>
		<visual>
			<geometry>
				<mesh filename="package://alex_description/meshes/cycloidal_arm/RightGripperYawLink.obj"/>
			</geometry>
			<origin rpy="0.0 0.0 0.0" xyz="0.0 0.0 0.0"/>
		</visual>
	</link>
	<!-- Right ARM IMU's -->
	<!-- Right Shoulder Pitch IMU Information -->
	<link name="RightShoulderPitchIMULink">
		<inertial>
			<mass value="0"/>
			<origin rpy="0 0 0" xyz="0 0 0"/>
			<inertia ixx="0.0" ixy="0.0" ixz="0.0" iyy="0.0" iyz="0.0" izz="0.0"/>
		</inertial>
	</link>
	<joint name="RightShoulderPitchIMUJoint" type="fixed">
		<origin rpy="3.141592 0 -1.57079632679" xyz="0.01432621 -0.10001299 -0.00245783"/>
		<axis xyz="0 0 1"/>
		<parent link="RightShoulderPitchLink"/>
		<child link="RightShoulderPitchIMULink"/>
	</joint>
	<gazebo reference="RightShoulderPitchIMULink">
		<sensor name="RightShoulderPitchIMU" type="imu">
			<always_on>true</always_on>
			<imu>
				<noise>
					<type>gaussian</type>
					<rate>
						<mean>0</mean>
						<stddev>0.0002</stddev>
						<bias_mean>7.5e-06</bias_mean>
						<bias_stddev>8e-07</bias_stddev>
					</rate>
					<accel>
						<mean>0</mean>
						<stddev>0.017</stddev>
						<bias_mean>0.1</bias_mean>
						<bias_stddev>0.001</bias_stddev>
					</accel>
				</noise>
			</imu>
		</sensor>
	</gazebo>

	<!-- Right ShoulderYaw IMU Note: in CAD this is the left bicep IMU -->
	<link name="RightShoulderYawIMULink">
		<inertial>
			<mass value="0"/>
			<origin rpy="0 0 0" xyz="0 0 0"/>
			<inertia ixx="0.0" ixy="0.0" ixz="0.0" iyy="0.0" iyz="0.0" izz="0.0"/>
		</inertial>
	</link>
	<joint name="RightShoulderYawIMUJoint" type="fixed">
		<origin rpy="-1.570796 0.0 0.314159" xyz="0.00119168 0.00914134 -0.19881468"/>
		<axis xyz="0 0 1"/>
		<parent link="RightShoulderYawLink"/>
		<child link="RightShoulderYawIMULink"/>
	</joint>
	<gazebo reference="RightShoulderYawIMULink">
		<sensor name="RightShoulderYawIMU" type="imu">
			<always_on>true</always_on>
			<pose>0 0 0 0 0 0</pose>
			<imu>
				<noise>
					<type>gaussian</type>
					<rate>
						<mean>0</mean>
						<stddev>0.0002</stddev>
						<bias_mean>7.5e-06</bias_mean>
						<bias_stddev>8e-07</bias_stddev>
					</rate>
					<accel>
						<mean>0</mean>
						<stddev>0.017</stddev>
						<bias_mean>0.1</bias_mean>
						<bias_stddev>0.001</bias_stddev>
					</accel>
				</noise>
			</imu>
		</sensor>
	</gazebo>

	<!-- Right Wrist Yaw IMU Note: in CAD this is the left bicep IMU -->
	<link name="RightWristYawIMULink">
		<inertial>
			<mass value="0"/>
			<origin rpy="0 0 0" xyz="0 0 0"/>
			<inertia ixx="0.0" ixy="0.0" ixz="0.0" iyy="0.0" iyz="0.0" izz="0.0"/>
		</inertial>
	</link>

	<joint name="RightWristYawIMUJoint" type="fixed">
		<origin rpy="1.571  0.0 1.571" xyz="-0.048986 0.011658 -0.149476"/>
		<axis xyz="0 0 1"/>
		<parent link="RightWristYawLink"/>
		<child link="RightWristYawIMULink"/>
	</joint>

	<gazebo reference="RightWristYawIMULink">
		<sensor name="RightWristYawIMU" type="imu">
			<always_on>true</always_on>
			<imu> <!-- placeholder tag for IMU --> </imu>
		</sensor>
	</gazebo>
	
	<!-- Gripper Fixed Joints -->

	<joint name="LeftGrippertAttachmentFixedJoint" type="fixed">
		<origin rpy="0 0 0" xyz="0 0 -0.0210000"/>
		<parent link="LeftGripperYawLink"/>
		<child link="LeftFlatHand"/>
    </joint>
		<joint name="RightGrippertAttachmentFixedJoint" type="fixed">
		<origin rpy="0 0 0" xyz="0 0 -0.0210000"/>
		<parent link="RightGripperYawLink"/>
		<child link="RightFlatHand"/>
    </joint>
	
	<!-- HAND LINKS -->
	<!-- Right Flat Hand -->
	<link name="RightFlatHand">
        <inertial>
            <mass value="0.3"/>
            <origin rpy="0 0 0" xyz="0.0 0.026463 -0.06227"/>
			<!-- Inertia tensor is ill conditioned. Can reduced ixy and iyz by an order of magnitude to see inertia ellipsoids. -->
            <inertia ixx="4.97311e-4" ixy="2.793e-4" ixz="-1.15e-7" iyy="3.66606e-4" iyz="1.3979e-4" izz="2.53076e-4" />
        </inertial>
        <visual name="RightFlatHandVisual">
			<origin rpy="0 1.57079632679 3.14159265359" xyz="0.0 0.0 0.0"/>
            <geometry>
                <mesh filename="package://flat_hand_description/meshes/FlatHands.obj"/>
            </geometry>
        </visual>
    </link>

	<!-- Left Flat Hand -->
	<link name="LeftFlatHand">
        <inertial>
            <mass value="0.3"/>
			<origin rpy="0 0 0" xyz="0.0 -0.026463 -0.06227"/>
			<!-- Inertia tensor is ill conditioned. Can reduced ixy and iyz by an order of magnitude to see inertia ellipsoids. -->
			<inertia ixx="4.97e-4" ixy="-2.793e-4" ixz="1.15e-7" iyy="3.666e-4" iyz="-1.398e-4" izz="2.531e-4" />
        </inertial>
        <visual name="LeftFlatHandVisual">
			<origin rpy="0 1.57079632679 0" xyz="0.0 0.0 0.0"/>
            <geometry>
                <mesh filename="package://flat_hand_description/meshes/FlatHands.obj"/>
            </geometry>
        </visual>
    </link>
</robot>
