<?xml version = "1.0" ?>
<robot name="Alex">

	<!-- Pelvis Base -->
	<link name="Pelvis">
	  <inertial>
		<mass value="10.0"/>
		<origin rpy="0 0 0" xyz="0.02 0.0 -0.02"/>
		<inertia ixx="0.0942" ixy="6.05E-06" ixz="0.000379" iyy="0.0416" iyz="3.37E-07" izz="0.112" />
	  </inertial>
	</link>

	<!-- pelvis_stim_imu -->
	  <joint name="PelvisStimIMUFixedJoint" type="fixed">
		<parent link="Pelvis"/>
		<child link="PelvisStimIMUMount"/>
		<origin xyz="-0.03133646 0.02237500 -0.07000000" rpy="0.0 3.141592 0.0"/>
	  </joint>

	<link name="PelvisStimIMUMount">
		<inertial>
		  <mass value="0.0" />
		  <origin xyz="0 0 0" rpy="0 0 0" />
		  <inertia ixx="0.0" ixy="0.0" ixz="0.0" iyy="0.0" iyz="0.0" izz="0.0" />
		</inertial>
	</link>

	<gazebo reference="PelvisStimIMUMount">
		<sensor name="PelvisStimImu" type="imu">
		  <always_on>1</always_on>
		  <update_rate>1000.0</update_rate>
		  <imu>
			<noise>
			  <type>gaussian</type>
			  <rate>
				<mean>0.0</mean>
				<stddev>2e-4</stddev>
				<bias_mean>0.0000075</bias_mean>
				<bias_stddev>0.0000008</bias_stddev>
			  </rate>
			  <accel>
				<mean>0.0</mean>
				<stddev>1.7e-2</stddev>
				<bias_mean>0.1</bias_mean>
				<bias_stddev>0.001</bias_stddev>
			  </accel>
			</noise>
		  </imu>
		</sensor>
	</gazebo>
	<!-- end pelvis stim imu -->

	<!-- Spine Joints -->
	<joint name="SpineYaw" type="revolute">
		<origin rpy="0 0 0" xyz="0.0 0.0 0.0" />
		<axis xyz="0 0 1" />
		<parent link="Pelvis" />
		<child link="SpineYawLink" />
		<limit effort="150" lower="-1.0472" upper="1.0472" velocity = "9.0" />
		<dynamics damping="0.05" friction="0.0"/>
    </joint>

	<joint name="SpineRoll" type="revolute">
		<origin rpy="0 0 0" xyz="-0.08 0 0.12" />
		<axis xyz="1 0 0" />
		<parent link="SpineYawLink" />
		<child link="SpineRollLink" />
		<limit effort="150.0" lower="-0.436332" upper="0.436332" velocity = "6.0" />
		<dynamics damping="0.05" friction="0.0"/>
	</joint>

	<joint name="SpinePitch" type="revolute">
		<origin rpy="0 0 0" xyz="0.12 0.0 0.0" />
		<axis xyz="0 1 0" />
		<parent link="SpineRollLink" />
		<child link="Torso" />
		<limit effort="250.0" lower="-0.523599" upper="1.0472" velocity = "6.0" />
		<dynamics damping="0.05" friction="0.0"/>
	</joint>

	<!-- Neck Joints -->
	<joint name="NeckYaw" type="revolute">
		<origin rpy="0 0 0" xyz="0.0 0.0 0.3" />
		<axis xyz="0 0 1" />
		<parent link="Torso" />
		<child link="NeckYawLink" />
		<limit effort="20" lower="-1.5708" upper="1.5708" velocity = "20" />
		<dynamics damping="0.05" friction="0.0"/>
	</joint>

	<joint name="NeckPitch" type="revolute">
		<origin rpy="0 0 0" xyz="0.0 0.0 0.173" />
		<axis xyz="0 1 0" />
		<parent link="NeckYawLink" />
		<child link="Head" />
		<limit effort="20" lower="-1.0472" upper="1.0472" velocity = "20" />
		<dynamics damping="0.05" friction="0.0"/>
	</joint>

	<!-- Spine Links -->
	<link name="SpineYawLink">
	  <inertial>
		<mass value="0.91"/>
		<origin rpy="0 0 0" xyz="-0.00853118 -2.697E-05 0.03791445"/>
		<inertia ixx="0.00374289408" ixy="1.25497934E-07" ixz="0.000271325072" iyy="0.00403002777" iyz="-1.38015692E-07" izz="0.0062129847" />
	  </inertial>
	</link>

	<link name="SpineRollLink">
	  <inertial>
		<mass value="0.44"/>
		<origin rpy="0 0 0" xyz="-0.01904983 7E-08 0.01979244"/>
		<inertia ixx="0.000373262301" ixy="-1.51441878E-10" ixz="-6.69067307E-05" iyy="0.000649978475" iyz="-1.27858402E-10" izz="0.000419408851" />
	  </inertial>
	</link>

	<!-- Torso Link -->
	<link name="Torso">
	  <inertial>
		<mass value="13.5"/>
		<origin rpy="0 0 0" xyz="-0.03613868 -2.81E-06 0.25908586"/>
		<inertia ixx="0.534504681" ixy="8.41519717E-05" ixz="-0.00672956305" iyy="0.505409852" iyz="0.000207996773" izz="0.379402013" />
	  </inertial>
	  <visual>
			<geometry>
				<mesh filename="package://alex_description/meshes/Torso.obj"/>
			</geometry>
			<origin rpy="0.0 0.0 0.0" xyz="0.0 0.0 0.0"/>
		  </visual>	
	</link>

	<!-- Neck and Head -->
	<!-- Inertia data is a placeholder -->
	<link name="NeckYawLink">
	  <inertial>
		<mass value="1.0"/>
		<origin rpy="0 0 0" xyz="0.0 0.0 0.1"/>
		<inertia 
			  ixx="0.0036746953546519796" 
			  ixy="1.5200537475756135E-5" 
			  ixz="-1.3155829305043117E-5"
			  iyy="0.003955455275643572" 
			  iyz="-9.878441058198549E-5" 
			  izz="0.0014329681446651732" />    
	  </inertial>
	  <!--visual>
			<geometry>
				<mesh filename="package://alex_description/meshes/NeckYaw.obj"/>
			</geometry>
			<origin rpy="0.0 0.0 0.0" xyz="0.0 0.0 0.0"/>
	   </visual-->	
	</link>

	<link name="Head">
	 <inertial>
		<mass value="3.0"/>
		<origin rpy="0 0 0" xyz="0.06 0.0 0.04"/>
		<inertia ixx="0.00345011" ixy="-0.0000073" ixz="0.0014225" iyy="0.00955764" iyz="-2.269e-7" izz="0.00881313" />
	  </inertial>
	  <visual>
			<geometry>
				<mesh filename="package://alex_description/meshes/Head.obj"/>
			</geometry>
			<origin rpy="0.0 0.0 0.0" xyz="0.0 0.0 0.0"/>
		  </visual>	
	</link>


	<!-- left upper arm joints -->
	<joint name="LeftShoulderPitch" type="revolute">
		<origin xyz="-0.025 0.1 0.21449" rpy="0.698132 0.0 0.0"   />
		<axis xyz="0.0 1.0 0.0" />
		<parent link="Torso" />
		<child link="LeftShoulderPitchLink" />
		<limit effort="150.0" lower="-3.141592" upper="1.22173" velocity = "9.0" />
		<dynamics damping="0.05" friction="0.0"/>
	</joint>
	
	<joint name="LeftShoulderRoll" type="revolute">
		<origin rpy="-0.698132 0.0 0.0" xyz="0.0 0.15676000 -0.01300000" />
		<axis xyz="1 0 0" />
		<parent link="LeftShoulderPitchLink" />
		<child link="LeftShoulderRollLink" />
		<limit effort="150.0" lower="-0.349066" upper="2.79253" velocity = "9.0" />
		<dynamics damping="0.05" friction="0.0"/>
	</joint>
	
	<joint name="LeftShoulderYaw" type="revolute">
		<origin rpy="0.0 0.0 0.0" xyz="0.0 0.035 0.0" />
		<axis xyz="0.0 0.0 1.0" />
		<parent link="LeftShoulderRollLink" />
		<child link="LeftShoulderYawLink" />
		<limit effort="80.0" lower="-1.91986" upper="1.22173" velocity = "11.5" />
		<dynamics damping="0.05" friction="0.0"/>
	</joint>
	
	<joint name="LeftElbowPitch" type="revolute">
		<origin rpy="0.0 0.0 0.0" xyz="0.015 0.0 -0.4" />
		<axis xyz="0.0 1.0 0.0" />
		<parent link="LeftShoulderYawLink" />
		<child link="LeftElbowPitchLink" />
		<limit effort="80.0" lower="-2.35619" upper="0.174532925" velocity = "11.5" />
		<dynamics damping="0.05" friction="0.0"/>
	</joint>
	
	<!-- left wrist joints -->
	<joint name="LeftWristYaw" type="revolute">
		<origin xyz="-0.015 0.0 0.0" rpy="0.0 0.0 0.0"   />
		<axis xyz="0.0 0.0 1.0" />
		<parent link="LeftElbowPitchLink" />
		<child link="LeftWristYawLink" />
		<limit effort="20.0" lower="-2.61799" upper="2.61799" velocity = "25.0" />
		<dynamics damping="0.05" friction="0.0"/>
	</joint>
	
	<joint name="LeftWristRoll" type="revolute">
		<origin xyz="0.0 -0.013 -0.25" rpy="0.0 0.0 0.0"/>
		<axis xyz="1 0 0" />
		<parent link="LeftWristYawLink" />
		<child link="LeftWristRollLink" />
		<limit effort="20.0" lower="-1.8326" upper="0.610865" velocity = "25.0" />
		<dynamics damping="0.05" friction="0.0"/>
	</joint>
	
	<joint name="LeftGripperYaw" type="revolute">
		<origin xyz="0.0 0.013 -0.031" rpy="0.0 0.0 0.0" />
		<axis xyz="0.0 0.0 1.0" />
		<parent link="LeftWristRollLink" />
		<child link="LeftGripperYawLink" />
		<limit effort="20.0" lower="-2.61799" upper="2.61799" velocity = "25.0" />
		<dynamics damping="0.05" friction="0.0"/>
	</joint>
	
	<!-- left upper arm links -->
	<link name="LeftShoulderPitchLink">
	  <inertial>
		<mass value="2.917"/>
		<origin rpy="0 0 0" xyz="-0.00117 0.1400097 -0.00621"/>
		<inertia ixx="0.0108367" ixy="1.356e-4" ixz="-2.666e-5" iyy="0.00498324" iyz="0.00090758" izz="0.01142661" />
	  </inertial>
	  <visual>
		<geometry>
		  <mesh filename="package://alex_description/meshes/cycloidal_arm/LeftShoulderPitchLink.obj"/>
		</geometry>
		<origin rpy="0.0 0.0 0.0" xyz="0.0 0.0 0.0"/>
	  </visual>
	</link>

	<link name="LeftShoulderRollLink">
	  <inertial>
		<mass value="1.17068"/>
		<origin rpy="0 0 0" xyz="0.01053 0.02124 -0.1052690"/>
		<inertia ixx="0.00787035" ixy="1.667e-4" ixz="-0.00075945" iyy="0.00727481" iyz="0.000988837" izz="0.00182144" />
	  </inertial>
	  <visual>
		<geometry>
		  <mesh filename="package://alex_description/meshes/cycloidal_arm/LeftShoulderRollLink.obj"/>
		</geometry>
		<origin rpy="0.0 0.0 0.0" xyz="0.0 0.0 0.0"/>
	  </visual>
	</link>

	<link name="LeftShoulderYawLink">
	  <inertial>
		<mass value="2.53059"/>
		<origin rpy="0 0 0" xyz="0.00479 0.00062 -0.3624141"/>
		<inertia ixx="0.02277422" ixy="5.053e-5" ixz="0.0012266" iyy="0.0225956" iyz="-2.571e-4" izz="0.00260312" />
	  </inertial>
	  <visual>
		<geometry>
		  <mesh filename="package://alex_description/meshes/cycloidal_arm/LeftShoulderYawLink.obj"/>
		</geometry>
		<origin rpy="0.0 0.0 0.0" xyz="0.0 0.0 0.0"/>
	  </visual>
	</link>
	
	<!-- left wrist links -->	
	<link name="LeftElbowPitchLink">
      <inertial>
        <mass value="0.4895385722366345"/>
        <origin xyz="-0.012039456382923622 -0.003781574950319319 -0.04998167188554722" rpy="0 0 0"/>        
      <inertia 
	    ixx="7.466682164602668E-4" 
		ixy="-4.9125185240164585E-6" 
		ixz="-3.118756072793259E-5" 
		iyy="6.697708130628391E-4" 
		iyz="1.4985943611036623E-4" 
		izz="4.976405971436793E-4" />    
	  </inertial>
      <visual>
        <geometry>
            <mesh filename="package://alex_description/meshes/cycloidal_arm/LeftElbowPitchLink.obj"/>
        </geometry>
        <origin rpy="0.0 0.0 0.0" xyz="0.0 0.0 0.0"/>
      </visual>
    </link>
	
	<link name="LeftWristYawLink">
    <inertial>
      <mass value="1.438"/>
        <origin xyz="-0.0024383302867828187 -5.246795816220965E-4 -0.1300914213150444" rpy="0 0 0"/>        
		<inertia 
		  ixx="0.0036746953546519796" 
		  ixy="1.5200537475756135E-5" 
		  ixz="-1.3155829305043117E-5"
		  iyy="0.003955455275643572" 
		  iyz="-9.878441058198549E-5" 
		  izz="0.0014329681446651732" />    
		</inertial>
    <visual>
      <geometry>
        <mesh filename="package://alex_description/meshes/cycloidal_arm/LeftWristYawLink.obj"/>
      </geometry>
      <origin rpy="0.0 0.0 0.0" xyz="0.0 0.0 0.0"/>
    </visual>
    </link>
	
	
    <link name="LeftWristRollLink">
      <inertial>
        <mass value="0.874"/>
        <origin xyz="1.5946763939368963E-4 0.012435479395687345 0.0016553711070014143" rpy="0 0 0"/>        
		<inertia 
		  ixx="5.09001424971436E-4"
		  ixy="-7.082123470616537E-6" 
		  ixz="-6.451042619821356E-6" 
		  iyy="5.251489793788867E-4" 
		  iyz="-1.2507083234598893E-6" 
		  izz="5.190882683529875E-4" />    
	  </inertial>
      <visual>
        <geometry>
            <mesh filename="package://alex_description/meshes/cycloidal_arm/LeftWristRollLink.obj"/>
        </geometry>
        <origin rpy="0.0 0.0 0.0" xyz="0.0 0.0 0.0"/>
      </visual>
    </link>

	
	<link name="LeftGripperYawLink">
	  <inertial>
		<mass value="0.3"/>
		<origin rpy="0 0 0" xyz="-0.00014709 -0.00037325 0.01033255"/>
		<inertia 
		ixx="0.00013926" 
		ixy="3.991e-8" 
		ixz="4.497e-7" 
		iyy="0.00014236" 
		iyz="-7.218e-7" 
		izz="0.00011005" />
	  </inertial>
	  <visual>
		<geometry>
		  <mesh filename="package://alex_description/meshes/cycloidal_arm/LeftGripperYawLink.obj"/>
		</geometry>
		<origin rpy="0.0 0.0 0.0" xyz="0.0 0.0 0.0"/>
	  </visual>
	</link>
	
	<!-- Right Upper Arm Joints -->
	<joint name="RightShoulderPitch" type="revolute">
    <origin xyz="-0.025 -0.1 0.21449" rpy="-0.698132 0.0 0.0"   />
		<axis xyz="0.0 1.0 0.0" />
		<parent link="Torso" />
		<child link="RightShoulderPitchLink" />
		<limit effort="1000" lower="-3.141592" upper="1.22173" velocity = "100" />
		<dynamics damping="0.05" friction="0.0"/>
	</joint>
	<joint name="RightShoulderRoll" type="revolute">
    <origin rpy="0.698132 0.0 0.0" xyz="0.0 -0.15676000 -0.01300000" />
		<axis xyz="1 0 0" />
		<parent link="RightShoulderPitchLink" />
		<child link="RightShoulderRollLink" />
    <limit effort="1000" lower="-2.79253" upper="0.349066" velocity = "100" />
		<dynamics damping="0.05" friction="0.0"/>
	</joint>
	<joint name="RightShoulderYaw" type="revolute">
		<origin rpy="0.0 0.0 0.0" xyz="0.0 -0.035 0.0" />
		<axis xyz="0.0 0.0 1.0" />
		<parent link="RightShoulderRollLink" />
		<child link="RightShoulderYawLink" />
		<limit effort="1000" lower="-1.22173" upper="1.91986" velocity = "100" />
		<dynamics damping="0.05" friction="0.0"/>
	</joint>
	<joint name="RightElbowPitch" type="revolute">
		<origin rpy="0.0 0.0 0.0" xyz="0.015 0.0 -0.4" />
		<axis xyz="0.0 1.0 0.0" />
		<parent link="RightShoulderYawLink" />
		<child link="RightElbowPitchLink" />
		<limit effort="1000" lower="-2.35619" upper="0.174532925" velocity = "100" />
		<dynamics damping="0.05" friction="0.0"/>
	</joint>

	<!-- right wrist joints -->
	<joint name="RightWristYaw" type="revolute">
		<origin xyz="-0.015 0.0 0.0" rpy="0.0 0.0 0.0"   />
		<axis xyz="0.0 0.0 1.0" />
		<parent link="RightElbowPitchLink" />
		<child link="RightWristYawLink" />
		<limit effort="20.0" lower="-2.61799" upper="2.61799" velocity = "25.0" />
		<dynamics damping="0.05" friction="0.0"/>
	</joint>
	
	<joint name="RightWristRoll" type="revolute">
		<origin xyz="0.0 0.013 -0.25" rpy="0.0 0.0 0.0"/>
		<axis xyz="1 0 0" />
		<parent link="RightWristYawLink" />
		<child link="RightWristRollLink" />
		<limit effort="20.0" lower="-0.610865" upper="1.8326" velocity = "25.0" />
		<dynamics damping="0.05" friction="0.0"/>
	</joint>
	
	<joint name="RightGripperYaw" type="revolute">
		<origin xyz="0.0 -0.013 -0.031" rpy="0.0 0.0 0.0" />
		<axis xyz="0.0 0.0 1.0" />
		<parent link="RightWristRollLink" />
		<child link="RightGripperYawLink" />
		<limit effort="20.0" lower="-2.61799" upper="2.61799" velocity = "25.0" />
		<dynamics damping="0.05" friction="0.0"/>
	</joint>
	
	<!-- Right Upper Arm Links -->
	<link name="RightShoulderPitchLink">
	  <inertial>
		<mass value="2.917"/>
		<origin rpy="0 0 0" xyz="-0.00117 -0.1400097 -0.00621"/>
		<inertia ixx="0.0108367" ixy="1.356e-4" ixz="-2.666e-5" iyy="0.00498324" iyz="0.00090758" izz="0.01142661" />
	  </inertial>
	  <visual>
		<geometry>
		  <mesh filename="package://alex_description/meshes/cycloidal_arm/RightShoulderPitchLink.obj"/>
		</geometry>
		<origin rpy="0.0 0.0 0.0" xyz="0.0 0.0 0.0"/>
	  </visual>
	</link>

	<link name="RightShoulderRollLink">
	  <inertial>
		<mass value="1.17068"/>
		<origin rpy="0 0 0" xyz="-0.01053 -0.02124 -0.1052690"/>
		<inertia ixx="0.00787035" ixy="-1.667e-4" ixz="-0.00075945" iyy="0.00727481" iyz="-0.000988837" izz="0.00182144" />
	  </inertial>
	  <visual>
		<geometry>
		  <mesh filename="package://alex_description/meshes/cycloidal_arm/RightShoulderRollLink.obj"/>
		</geometry>
		<origin rpy="0.0 0.0 0.0" xyz="0.0 0.0 0.0"/>
	  </visual>
	</link>

	<link name="RightShoulderYawLink">
	  <inertial>
		<mass value="2.53059"/>
		<origin rpy="0 0 0" xyz="0.00479 0.00062 -0.3624141"/>
		<inertia ixx="0.02277422" ixy="5.053e-5" ixz="0.0012266" iyy="0.0225956" iyz="-2.571e-4" izz="0.00260312" />
	  </inertial>
	  <visual>
		<geometry>
		  <mesh filename="package://alex_description/meshes/cycloidal_arm/RightShoulderYawLink.obj"/>
		</geometry>
		<origin rpy="0.0 0.0 0.0" xyz="0.0 0.0 0.0"/>
	  </visual>
	</link>

	<!-- right wrist links -->	
	<link name="RightElbowPitchLink">
      <inertial>
        <mass value="0.4895385722366345"/>
        <origin xyz="-0.012039456382923622 0.003781574950319319 -0.04998167188554722" rpy="0 0 0"/>        
		  <inertia 
			ixx="7.466682164602668E-4" 
			ixy="-4.9125185240164585E-6" 
			ixz="-3.118756072793259E-5" 
			iyy="6.697708130628391E-4" 
			iyz="1.4985943611036623E-4" 
			izz="4.976405971436793E-4" />    
	  </inertial>
      <visual>
        <geometry>
            <mesh filename="package://alex_description/meshes/cycloidal_arm/RightElbowPitchLink.obj"/>
        </geometry>
        <origin rpy="0.0 0.0 0.0" xyz="0.0 0.0 0.0"/>
      </visual>
    </link>
	
	<link name="RightWristYawLink">
    <inertial>
      <mass value="1.5075249788801466"/>
        <origin xyz="-0.0024383302867828187 5.246795816220965E-4 -0.1300914213150444" rpy="0 0 0"/>        
		<inertia 
		  ixx="0.0036746953546519796" 
		  ixy="1.5200537475756135E-5" 
		  ixz="-1.3155829305043117E-5"
		  iyy="0.003955455275643572" 
		  iyz="-9.878441058198549E-5" 
		  izz="0.0014329681446651732" />    
		</inertial>
    <visual>
      <geometry>
        <mesh filename="package://alex_description/meshes/cycloidal_arm/RightWristYawLink.obj"/>
      </geometry>
      <origin rpy="0.0 0.0 0.0" xyz="0.0 0.0 0.0"/>
    </visual>
    </link>
	
    <link name="RightWristRollLink">
      <inertial>
        <mass value="0.6953487750589724"/>
        <origin xyz="1.5946763939368963E-4 -0.012435479395687345 0.0016553711070014143" rpy="0 0 0"/>        
		<inertia 
		  ixx="5.09001424971436E-4"
		  ixy="-7.082123470616537E-6" 
		  ixz="-6.451042619821356E-6" 
		  iyy="5.251489793788867E-4" 
		  iyz="-1.2507083234598893E-6" 
		  izz="5.190882683529875E-4" />    
	  </inertial>
      <visual>
        <geometry>
            <mesh filename="package://alex_description/meshes/cycloidal_arm/RightWristRollLink.obj"/>
        </geometry>
        <origin rpy="0.0 0.0 0.0" xyz="0.0 0.0 0.0"/>
      </visual>
    </link>

	<link name="RightGripperYawLink">
	  <inertial>
		<mass value="0.3"/>
		<origin rpy="0 0 0" xyz="-0.00014709 0.00037325 0.01033255"/>
		<inertia 
		ixx="0.00013926" 
		ixy="3.991e-8" 
		ixz="4.497e-7" 
		iyy="0.00014236" 
		iyz="-7.218e-7" 
		izz="0.00011005" />
	  </inertial>
	  <visual>
		<geometry>
		  <mesh filename="package://alex_description/meshes/cycloidal_arm/RightGripperYawLink.obj"/>
		</geometry>
		<origin rpy="0.0 0.0 0.0" xyz="0.0 0.0 0.0"/>
	  </visual>
	</link>

	<!-- Gripper Fixed Joints -->
	<joint name="RightGrippertAttachmentFixedJoint" type="fixed">
		<origin rpy="0 0 0" xyz="0 0 -0.0210000"/>
		<parent link="RightGripperYawLink"/>
		<child link="RightSakePalmLink"/>
    </joint>
	
	<joint name="LeftGrippertAttachmentFixedJoint" type="fixed">
		<origin rpy="0 0 0" xyz="0 0 -0.0210000"/>
		<parent link="LeftGripperYawLink"/>
		<child link="LeftSakePalmLink"/>
    </joint>	

	<!-- Right Sake Gripper -->
	<link name="RightSakePalmLink">
        <inertial>
            <mass value="0.3"/>
            <origin rpy="0 0 0" xyz="0.01 0.0 -0.06"/>
            <inertia ixx="5e-4" ixy="0.0" ixz="0.0" iyy="3e-4" iyz="0.0" izz="3e-4" />
        </inertial>
        <visual name="RightSakePalmLinkVisual">
            <origin xyz="0.0 0.0 0.0" rpy="0 0 0"/>
            <geometry>
                <mesh filename="package://sake_description/meshes/SakePalmLink.obj"/>
            </geometry>
        </visual>
    </link>
	
	<joint name="RightSakeBaseFingerJoint1" type="revolute">
        <origin xyz="0.0 0.0299 -0.0754" rpy="-0.25 0.0 0.0"/>
        <axis xyz="1.0 0.0 0.0"/>
        <parent link="RightSakePalmLink"/>
        <child link="RightSakeBaseFingerLink1"/>
        <dynamics damping="0.05" friction="0.0"/>
        <limit effort="1.0" lower="-0.06" upper="1.9" velocity="3.67"/>
    </joint>
    <joint name="RightSakeKnuckle1" type="revolute">
        <origin xyz="0.0 0.0 -0.052" rpy="0.0 0.0 0.0"/>
        <axis xyz="1.0 0.0 0.0"/>
        <parent link="RightSakeBaseFingerLink1"/>
        <child link="RightSakeFingerTip1"/>
        <dynamics damping="0.05" friction="0.0"/>
        <limit effort="1.0" lower="-1.0" upper="0.0" velocity="3.67"/>
    </joint>
    <joint name="RightSakeBaseFingerJoint2" type="revolute">
        <origin xyz="0.0 -0.0299 -0.0754" rpy="0.25 0.0 0.0"/>
        <axis xyz="-1.0 0.0 0.0"/>
        <parent link="RightSakePalmLink"/>
        <child link="RightSakeBaseFingerLink2"/>
        <dynamics damping="0.05" friction="0.0"/>
        <limit effort="1.0" lower="-0.06" upper="1.9" velocity="3.67"/>
    </joint>
    <joint name="RightSakeKnuckle2" type="revolute">
        <origin xyz="0.0 0.0 -0.052" rpy="0.0 0.0 0.0"/>
        <axis xyz="-1.0 0.0 0.0"/>
        <parent link="RightSakeBaseFingerLink2"/>
        <child link="RightSakeFingerTip2"/>
        <dynamics damping="0.05" friction="0.0"/>
        <limit effort="1.0" lower="-1.0" upper="0.0" velocity="3.67"/>
	</joint>
		
	<link name="RightSakeBaseFingerLink1">
        <inertial>
            <mass value="0.05"/>
            <origin xyz="0.0 0.0 0.0" rpy="0.0 0.0 3.142"/>
            <inertia ixx="0.00001" ixy="0.0" ixz="0.0" iyy="0.00001" iyz="0.0" izz="0.00001"/>
        </inertial>
        <visual name="RIGHT_GRIPPER_ROLL1_LINK_visual">
            <origin xyz="0.0 0.0 0.0" rpy="1.571 0.0 0.0"/>
            <geometry>
                <mesh filename="package://sake_description/meshes/sake_finger_knuckle.obj"/>
            </geometry>
        </visual>
    </link>
    <link name="RightSakeFingerTip1">
        <inertial>
            <mass value="0.05"/>
            <origin xyz="0.0 0.0 0.0" rpy="0.0 0.0 0.0"/>
            <inertia ixx="0.00001" ixy="0.0" ixz="0.0" iyy="0.00001" iyz="0.0" izz="0.00001"/>
        </inertial>
        <visual name="RIGHT_GRIPPER_ROLL1_LINK_visual">
            <origin xyz="0.0 0.0 0.0" rpy="1.571 0.0 3.142"/>
            <geometry>
                <mesh filename="package://sake_description/meshes/sake_finger_tip.obj"/>
            </geometry>
        </visual>
    </link>
    <link name="RightSakeBaseFingerLink2">
        <inertial>
            <mass value="0.05"/>
            <origin xyz="0.0 0.0 0.0" rpy="0.0 0.0 0.0"/>
            <inertia ixx="0.00001" ixy="0.0" ixz="0.0" iyy="0.00001" iyz="0.0" izz="0.00001"/>
        </inertial>
        <visual name="RIGHT_GRIPPER_ROLL2_LINK_visual">
            <origin xyz="0.0 0.0 0.0" rpy="1.571 0.0 0.0"/>
            <geometry>
                <mesh filename="package://sake_description/meshes/sake_finger_knuckle.obj"/>
            </geometry>
        </visual>
    </link>
    <link name="RightSakeFingerTip2">
        <inertial>
            <mass value="0.05"/>
            <origin xyz="0.0 0.0 0.0" rpy="0.0 0.0 0.0"/>
            <inertia ixx="0.00001" ixy="0.0" ixz="0.0" iyy="0.00001" iyz="0.0" izz="0.00001"/>
        </inertial>
        <visual name="RIGHT_GRIPPER_ROLL1_LINK_visual">
            <origin xyz="0.0 0.0 0.0" rpy="1.571 0.0 0.0"/>
            <geometry>
                <mesh filename="package://sake_description/meshes/sake_finger_tip.obj"/>
            </geometry>
        </visual>
    </link>
	
	<!-- Left Sake Gripper -->
	<link name="LeftSakePalmLink">
        <inertial>
            <mass value="0.3"/>
            <origin rpy="0 0 0" xyz="0.01 0.0 -0.06"/>
            <inertia ixx="5e-4" ixy="0.0" ixz="0.0" iyy="3e-4" iyz="0.0" izz="3e-4" />
        </inertial>
        <visual name="LeftSakePalmLinkVisual">
            <origin xyz="0.0 0.0 0.0" rpy="0 0 0"/>
            <geometry>
                <mesh filename="package://sake_description/meshes/SakePalmLink.obj"/>
            </geometry>
        </visual>
    </link>
	
	<joint name="LeftSakeBaseFingerJoint1" type="revolute">
        <origin xyz="0.0 0.0299 -0.0754" rpy="-0.25 0.0 0.0"/>
        <axis xyz="1.0 0.0 0.0"/>
        <parent link="LeftSakePalmLink"/>
        <child link="LeftSakeBaseFingerLink1"/>
        <dynamics damping="0.05" friction="0.0"/>
        <limit effort="1.0" lower="-0.06" upper="1.9" velocity="3.67"/>
    </joint>
    <joint name="LeftSakeKnuckle1" type="revolute">
        <origin xyz="0.0 0.0 -0.052" rpy="0.0 0.0 0.0"/>
        <axis xyz="1.0 0.0 0.0"/>
        <parent link="LeftSakeBaseFingerLink1"/>
        <child link="LeftSakeFingerTip1"/>
        <dynamics damping="0.05" friction="0.0"/>
        <limit effort="1.0" lower="-1.0" upper="0.0" velocity="3.67"/>
    </joint>
    <joint name="LeftSakeBaseFingerJoint2" type="revolute">
        <origin xyz="0.0 -0.0299 -0.0754" rpy="0.25 0.0 0.0"/>
        <axis xyz="-1.0 0.0 0.0"/>
        <parent link="LeftSakePalmLink"/>
        <child link="LeftSakeBaseFingerLink2"/>
        <dynamics damping="0.05" friction="0.0"/>
        <limit effort="1.0" lower="-0.06" upper="1.9" velocity="3.67"/>
    </joint>
    <joint name="LeftSakeKnuckle2" type="revolute">
        <origin xyz="0.0 0.0 -0.052" rpy="0.0 0.0 0.0"/>
        <axis xyz="-1.0 0.0 0.0"/>
        <parent link="LeftSakeBaseFingerLink2"/>
        <child link="LeftSakeFingerTip2"/>
        <dynamics damping="0.05" friction="0.0"/>
        <limit effort="1.0" lower="-1.0" upper="0.0" velocity="3.67"/>
    </joint>
	
	<link name="LeftSakeBaseFingerLink1">
        <inertial>
            <mass value="0.05"/>
            <origin xyz="0.0 0.0 0.0" rpy="0.0 0.0 0.0"/>
            <inertia ixx="0.00001" ixy="0.0" ixz="0.0" iyy="0.00001" iyz="0.0" izz="0.00001"/>
        </inertial>
        <visual name="LeftSakeBaseFingerLink1Visual">
            <origin xyz="0.0 0.0 0.0" rpy="1.571 0.0 3.142"/>
            <geometry>
                <mesh filename="package://sake_description/meshes/sake_finger_knuckle.obj"/>
            </geometry>
        </visual>
    </link>
    <link name="LeftSakeFingerTip1">
        <inertial>
            <mass value="0.05"/>
            <origin xyz="0.0 0.0 0.0" rpy="0.0 0.0 0.0"/>
            <inertia ixx="0.00001" ixy="0.0" ixz="0.0" iyy="0.00001" iyz="0.0" izz="0.00001"/>
        </inertial>
        <visual name="LeftSakeFingerTip1Visual">
            <origin xyz="0.0 0.0 0.0" rpy="1.571 0.0 3.142"/>
            <geometry>
                <mesh filename="package://sake_description/meshes/sake_finger_tip.obj"/>
            </geometry>
        </visual>
    </link>
    <link name="LeftSakeBaseFingerLink2">
        <inertial>
            <mass value="0.05"/>
            <origin xyz="0.0 0.0 0.0" rpy="0.0 0.0 0.0"/>
            <inertia ixx="0.00001" ixy="0.0" ixz="0.0" iyy="0.00001" iyz="0.0" izz="0.00001"/>
        </inertial>
        <visual name="LeftSakeBaseFingerLink2Visual">
            <origin xyz="0.0 0.0 0.0" rpy="1.571 0.0 0.0"/>
            <geometry>
                <mesh filename="package://sake_description/meshes/sake_finger_knuckle.obj"/>
            </geometry>
        </visual>
    </link>
    <link name="LeftSakeFingerTip2">
        <inertial>
            <mass value="0.05"/>
            <origin xyz="0.0 0.0 0.0" rpy="0.0 0.0 0.0"/>
            <inertia ixx="0.00001" ixy="0.0" ixz="0.0" iyy="0.00001" iyz="0.0" izz="0.00001"/>
        </inertial>
        <visual name="LeftSakeFingerTip2Visual">
            <origin xyz="0.0 0.0 0.0" rpy="1.571 0.0 0.0"/>
            <geometry>
                <mesh filename="package://sake_description/meshes/sake_finger_tip.obj"/>
            </geometry>
        </visual>
    </link>
	
    <!-- __________________________ IMUS ______________________ -->

    <!-- IMU Information -->
    <link name="LeftShoulderPitchIMULink">
        <inertial>
            <mass value="0"/>
            <origin rpy="0 0 0" xyz="0 0 0"/>
            <inertia ixx="0.0" ixy="0.0" ixz="0.0" iyy="0.0" iyz="0.0" izz="0.0"/>
        </inertial>
    </link>
    <!-- LEFT SHOULDER PITCH IMU Information -->
    <joint name="LeftShoulderPitchIMUJoint" type="fixed">
        <origin rpy="-1.570796 1.570796 0" xyz="0.0174 0.06944 -0.03025"/>
        <axis xyz="0 0 1"/>
        <parent link="LeftShoulderPitchLink"/>
        <child link="LeftShoulderPitchIMULink"/>
    </joint>
    <gazebo reference="LeftShoulderPitchIMULink">
        <sensor name="LeftShoulderPitchIMU" type="imu">
            <always_on>true</always_on>
            <imu>
                <noise>
                    <type>gaussian</type>
                    <rate>
                        <mean>0</mean>
                        <stddev>0.0002</stddev>
                        <bias_mean>7.5e-06</bias_mean>
                        <bias_stddev>8e-07</bias_stddev>
                    </rate>
                    <accel>
                        <mean>0</mean>
                        <stddev>0.017</stddev>
                        <bias_mean>0.1</bias_mean>
                        <bias_stddev>0.001</bias_stddev>
                    </accel>
                </noise>
            </imu>
        </sensor>
    </gazebo>

    <!-- ShoulderYaw IMU -->
    <!-- Note: in CAD this is the left bicep IMU -->
    <link name="LeftShoulderYawIMULink">
        <inertial>
            <mass value="0"/>
            <origin rpy="0 0 0" xyz="0 0 0"/>
            <inertia ixx="0.0" ixy="0.0" ixz="0.0" iyy="0.0" iyz="0.0" izz="0.0"/>
        </inertial>
    </link>
    <joint name="LeftShoulderYawIMUJoint" type="fixed">
        <origin rpy="-1.570796 3.1415926 -0.314159" xyz="-0.00763459 -0.0123324 -0.318"/>
        <axis xyz="0 0 1"/>
        <parent link="LeftShoulderYawLink"/>
        <child link="LeftShoulderYawIMULink"/>
    </joint>
    <gazebo reference="LeftShoulderYawIMULink">
        <sensor name="LeftShoulderYawIMU" type="imu">
            <always_on>true</always_on>
            <pose>0 0 0 0 0 0</pose>
            <imu>
                <noise>
                    <type>gaussian</type>
                    <rate>
                        <mean>0</mean>
                        <stddev>0.0002</stddev>
                        <bias_mean>7.5e-06</bias_mean>
                        <bias_stddev>8e-07</bias_stddev>
                    </rate>
                    <accel>
                        <mean>0</mean>
                        <stddev>0.017</stddev>
                        <bias_mean>0.1</bias_mean>
                        <bias_stddev>0.001</bias_stddev>
                    </accel>
                </noise>
            </imu>
        </sensor>
    </gazebo>

	<!-- Wrist Yaw IMU -->
    <!-- Note: in CAD this is the left bicep IMU -->
    <link name="LeftWristYawIMULink">
        <inertial>
            <mass value="0"/>
            <origin rpy="0 0 0" xyz="0 0 0"/>
            <inertia ixx="0.0" ixy="0.0" ixz="0.0" iyy="0.0" iyz="0.0" izz="0.0"/>
        </inertial>
    </link>
	
    <joint name="LeftWristYawIMUJoint" type="fixed">
        <origin rpy="1.571  0.0 1.571" xyz="-0.033554 0.010450 -0.148527"/>
        <axis xyz="0 0 1"/>
        <parent link="LeftWristYawLink"/>
        <child link="LeftWristYawIMULink"/>
    </joint>
	
    <gazebo reference="LeftWristYawIMULink">
        <sensor name="LeftWristYawIMU" type="imu">
            <always_on>true</always_on>
            <imu> <!-- placeholder tag for IMU --> </imu>
        </sensor>
    </gazebo>
</robot>
